
[2025-01-15 00:23:55 +0000] [21813] [INFO] Starting gunicorn 23.0.0
[2025-01-15 00:23:55 +0000] [21813] [INFO] Listening at: http://127.0.0.1:8000 (21813)
[2025-01-15 00:23:55 +0000] [21813] [INFO] Using worker: sync
[2025-01-15 00:23:55 +0000] [21815] [INFO] Booting worker with pid: 21815
[2025-01-15 00:23:55 +0000] [21818] [INFO] Booting worker with pid: 21818
[2025-01-15 00:23:55 +0000] [21819] [INFO] Booting worker with pid: 21819
[2025-01-15 00:23:55 +0000] [21820] [INFO] Booting worker with pid: 21820
[2025-01-15 00:23:57 +0000] [21815] [ERROR] Exception in worker process
Traceback (most recent call last):
  File "/home/ec2-user/flask_miniproject1/.venv/lib64/python3.12/site-packages/gunicorn/arbiter.py", line 608, in spawn_worker
    worker.init_process()
  File "/home/ec2-user/flask_miniproject1/.venv/lib64/python3.12/site-packages/gunicorn/workers/base.py", line 135, in init_process
    self.load_wsgi()
  File "/home/ec2-user/flask_miniproject1/.venv/lib64/python3.12/site-packages/gunicorn/workers/base.py", line 147, in load_wsgi
    self.wsgi = self.app.wsgi()
                ^^^^^^^^^^^^^^^
  File "/home/ec2-user/flask_miniproject1/.venv/lib64/python3.12/site-packages/gunicorn/app/base.py", line 66, in wsgi
    self.callable = self.load()
                    ^^^^^^^^^^^
  File "/home/ec2-user/flask_miniproject1/.venv/lib64/python3.12/site-packages/gunicorn/app/wsgiapp.py", line 57, in load
    return self.load_wsgiapp()
           ^^^^^^^^^^^^^^^^^^^
  File "/home/ec2-user/flask_miniproject1/.venv/lib64/python3.12/site-packages/gunicorn/app/wsgiapp.py", line 47, in load_wsgiapp
    return util.import_app(self.app_uri)
           ^^^^^^^^^^^^^^^^^^^^^^^^^^^^^
  File "/home/ec2-user/flask_miniproject1/.venv/lib64/python3.12/site-packages/gunicorn/util.py", line 370, in import_app
    mod = importlib.import_module(module)
          ^^^^^^^^^^^^^^^^^^^^^^^^^^^^^^^
  File "/usr/lib64/python3.12/importlib/__init__.py", line 90, in import_module
    return _bootstrap._gcd_import(name[level:], package, level)
           ^^^^^^^^^^^^^^^^^^^^^^^^^^^^^^^^^^^^^^^^^^^^^^^^^^^^
  File "<frozen importlib._bootstrap>", line 1387, in _gcd_import
  File "<frozen importlib._bootstrap>", line 1360, in _find_and_load
  File "<frozen importlib._bootstrap>", line 1331, in _find_and_load_unlocked
  File "<frozen importlib._bootstrap>", line 935, in _load_unlocked
  File "<frozen importlib._bootstrap_external>", line 995, in exec_module
  File "<frozen importlib._bootstrap>", line 488, in _call_with_frames_removed
  File "/home/ec2-user/flask_miniproject1/wsgi.py", line 3, in <module>
    app = create_app()
          ^^^^^^^^^^^^
  File "/home/ec2-user/flask_miniproject1/app/__init__.py", line 32, in create_app
    from .routes.choices import choices_blp
  File "/home/ec2-user/flask_miniproject1/app/routes/choices.py", line 27
    choices = Choices.query.all()
    ^^^^^^^
IndentationError: expected an indented block after function definition on line 26
[2025-01-15 00:23:57 +0000] [21815] [INFO] Worker exiting (pid: 21815)
[2025-01-15 00:23:57 +0000] [21818] [ERROR] Exception in worker process
Traceback (most recent call last):
  File "/home/ec2-user/flask_miniproject1/.venv/lib64/python3.12/site-packages/gunicorn/arbiter.py", line 608, in spawn_worker
    worker.init_process()
  File "/home/ec2-user/flask_miniproject1/.venv/lib64/python3.12/site-packages/gunicorn/workers/base.py", line 135, in init_process
    self.load_wsgi()
  File "/home/ec2-user/flask_miniproject1/.venv/lib64/python3.12/site-packages/gunicorn/workers/base.py", line 147, in load_wsgi
    self.wsgi = self.app.wsgi()
                ^^^^^^^^^^^^^^^
  File "/home/ec2-user/flask_miniproject1/.venv/lib64/python3.12/site-packages/gunicorn/app/base.py", line 66, in wsgi
    self.callable = self.load()
                    ^^^^^^^^^^^
  File "/home/ec2-user/flask_miniproject1/.venv/lib64/python3.12/site-packages/gunicorn/app/wsgiapp.py", line 57, in load
    return self.load_wsgiapp()
           ^^^^^^^^^^^^^^^^^^^
  File "/home/ec2-user/flask_miniproject1/.venv/lib64/python3.12/site-packages/gunicorn/app/wsgiapp.py", line 47, in load_wsgiapp
    return util.import_app(self.app_uri)
           ^^^^^^^^^^^^^^^^^^^^^^^^^^^^^
  File "/home/ec2-user/flask_miniproject1/.venv/lib64/python3.12/site-packages/gunicorn/util.py", line 370, in import_app
    mod = importlib.import_module(module)
          ^^^^^^^^^^^^^^^^^^^^^^^^^^^^^^^
  File "/usr/lib64/python3.12/importlib/__init__.py", line 90, in import_module
    return _bootstrap._gcd_import(name[level:], package, level)
           ^^^^^^^^^^^^^^^^^^^^^^^^^^^^^^^^^^^^^^^^^^^^^^^^^^^^
  File "<frozen importlib._bootstrap>", line 1387, in _gcd_import
  File "<frozen importlib._bootstrap>", line 1360, in _find_and_load
  File "<frozen importlib._bootstrap>", line 1331, in _find_and_load_unlocked
  File "<frozen importlib._bootstrap>", line 935, in _load_unlocked
  File "<frozen importlib._bootstrap_external>", line 995, in exec_module
  File "<frozen importlib._bootstrap>", line 488, in _call_with_frames_removed
  File "/home/ec2-user/flask_miniproject1/wsgi.py", line 3, in <module>
    app = create_app()
          ^^^^^^^^^^^^
  File "/home/ec2-user/flask_miniproject1/app/__init__.py", line 32, in create_app
    from .routes.choices import choices_blp
  File "/home/ec2-user/flask_miniproject1/app/routes/choices.py", line 27
    choices = Choices.query.all()
    ^^^^^^^
IndentationError: expected an indented block after function definition on line 26
[2025-01-15 00:23:57 +0000] [21818] [INFO] Worker exiting (pid: 21818)
[2025-01-15 00:23:57 +0000] [21819] [ERROR] Exception in worker process
Traceback (most recent call last):
  File "/home/ec2-user/flask_miniproject1/.venv/lib64/python3.12/site-packages/gunicorn/arbiter.py", line 608, in spawn_worker
    worker.init_process()
  File "/home/ec2-user/flask_miniproject1/.venv/lib64/python3.12/site-packages/gunicorn/workers/base.py", line 135, in init_process
    self.load_wsgi()
  File "/home/ec2-user/flask_miniproject1/.venv/lib64/python3.12/site-packages/gunicorn/workers/base.py", line 147, in load_wsgi
    self.wsgi = self.app.wsgi()
                ^^^^^^^^^^^^^^^
  File "/home/ec2-user/flask_miniproject1/.venv/lib64/python3.12/site-packages/gunicorn/app/base.py", line 66, in wsgi
    self.callable = self.load()
                    ^^^^^^^^^^^
  File "/home/ec2-user/flask_miniproject1/.venv/lib64/python3.12/site-packages/gunicorn/app/wsgiapp.py", line 57, in load
    return self.load_wsgiapp()
           ^^^^^^^^^^^^^^^^^^^
  File "/home/ec2-user/flask_miniproject1/.venv/lib64/python3.12/site-packages/gunicorn/app/wsgiapp.py", line 47, in load_wsgiapp
    return util.import_app(self.app_uri)
           ^^^^^^^^^^^^^^^^^^^^^^^^^^^^^
  File "/home/ec2-user/flask_miniproject1/.venv/lib64/python3.12/site-packages/gunicorn/util.py", line 370, in import_app
    mod = importlib.import_module(module)
          ^^^^^^^^^^^^^^^^^^^^^^^^^^^^^^^
  File "/usr/lib64/python3.12/importlib/__init__.py", line 90, in import_module
    return _bootstrap._gcd_import(name[level:], package, level)
           ^^^^^^^^^^^^^^^^^^^^^^^^^^^^^^^^^^^^^^^^^^^^^^^^^^^^
  File "<frozen importlib._bootstrap>", line 1387, in _gcd_import
  File "<frozen importlib._bootstrap>", line 1360, in _find_and_load
  File "<frozen importlib._bootstrap>", line 1331, in _find_and_load_unlocked
  File "<frozen importlib._bootstrap>", line 935, in _load_unlocked
  File "<frozen importlib._bootstrap_external>", line 995, in exec_module
  File "<frozen importlib._bootstrap>", line 488, in _call_with_frames_removed
  File "/home/ec2-user/flask_miniproject1/wsgi.py", line 3, in <module>
    app = create_app()
          ^^^^^^^^^^^^
  File "/home/ec2-user/flask_miniproject1/app/__init__.py", line 32, in create_app
    from .routes.choices import choices_blp
  File "/home/ec2-user/flask_miniproject1/app/routes/choices.py", line 27
    choices = Choices.query.all()
    ^^^^^^^
IndentationError: expected an indented block after function definition on line 26
[2025-01-15 00:23:57 +0000] [21819] [INFO] Worker exiting (pid: 21819)
[2025-01-15 00:23:57 +0000] [21820] [ERROR] Exception in worker process
Traceback (most recent call last):
  File "/home/ec2-user/flask_miniproject1/.venv/lib64/python3.12/site-packages/gunicorn/arbiter.py", line 608, in spawn_worker
    worker.init_process()
  File "/home/ec2-user/flask_miniproject1/.venv/lib64/python3.12/site-packages/gunicorn/workers/base.py", line 135, in init_process
    self.load_wsgi()
  File "/home/ec2-user/flask_miniproject1/.venv/lib64/python3.12/site-packages/gunicorn/workers/base.py", line 147, in load_wsgi
    self.wsgi = self.app.wsgi()
                ^^^^^^^^^^^^^^^
  File "/home/ec2-user/flask_miniproject1/.venv/lib64/python3.12/site-packages/gunicorn/app/base.py", line 66, in wsgi
    self.callable = self.load()
                    ^^^^^^^^^^^
  File "/home/ec2-user/flask_miniproject1/.venv/lib64/python3.12/site-packages/gunicorn/app/wsgiapp.py", line 57, in load
    return self.load_wsgiapp()
           ^^^^^^^^^^^^^^^^^^^
  File "/home/ec2-user/flask_miniproject1/.venv/lib64/python3.12/site-packages/gunicorn/app/wsgiapp.py", line 47, in load_wsgiapp
    return util.import_app(self.app_uri)
           ^^^^^^^^^^^^^^^^^^^^^^^^^^^^^
  File "/home/ec2-user/flask_miniproject1/.venv/lib64/python3.12/site-packages/gunicorn/util.py", line 370, in import_app
    mod = importlib.import_module(module)
          ^^^^^^^^^^^^^^^^^^^^^^^^^^^^^^^
  File "/usr/lib64/python3.12/importlib/__init__.py", line 90, in import_module
    return _bootstrap._gcd_import(name[level:], package, level)
           ^^^^^^^^^^^^^^^^^^^^^^^^^^^^^^^^^^^^^^^^^^^^^^^^^^^^
  File "<frozen importlib._bootstrap>", line 1387, in _gcd_import
  File "<frozen importlib._bootstrap>", line 1360, in _find_and_load
  File "<frozen importlib._bootstrap>", line 1331, in _find_and_load_unlocked
  File "<frozen importlib._bootstrap>", line 935, in _load_unlocked
  File "<frozen importlib._bootstrap_external>", line 995, in exec_module
  File "<frozen importlib._bootstrap>", line 488, in _call_with_frames_removed
  File "/home/ec2-user/flask_miniproject1/wsgi.py", line 3, in <module>
    app = create_app()
          ^^^^^^^^^^^^
  File "/home/ec2-user/flask_miniproject1/app/__init__.py", line 32, in create_app
    from .routes.choices import choices_blp
  File "/home/ec2-user/flask_miniproject1/app/routes/choices.py", line 27
    choices = Choices.query.all()
    ^^^^^^^
IndentationError: expected an indented block after function definition on line 26
[2025-01-15 00:23:57 +0000] [21820] [INFO] Worker exiting (pid: 21820)
[2025-01-15 00:23:57 +0000] [21813] [ERROR] Worker (pid:21815) exited with code 3
[2025-01-15 00:23:57 +0000] [21813] [ERROR] Worker (pid:21818) was sent SIGTERM!
[2025-01-15 00:23:57 +0000] [21813] [ERROR] Worker (pid:21820) was sent SIGTERM!
[2025-01-15 00:23:57 +0000] [21813] [ERROR] Worker (pid:21819) was sent SIGTERM!
[2025-01-15 00:23:57 +0000] [21813] [ERROR] Shutting down: Master
[2025-01-15 00:23:57 +0000] [21813] [ERROR] Reason: Worker failed to boot.
[2025-01-15 00:29:28 +0000] [22637] [INFO] Starting gunicorn 23.0.0
[2025-01-15 00:29:28 +0000] [22637] [INFO] Listening at: http://127.0.0.1:8000 (22637)
[2025-01-15 00:29:28 +0000] [22637] [INFO] Using worker: sync
[2025-01-15 00:29:28 +0000] [22639] [INFO] Booting worker with pid: 22639
[2025-01-15 00:29:28 +0000] [22640] [INFO] Booting worker with pid: 22640
[2025-01-15 00:29:28 +0000] [22642] [INFO] Booting worker with pid: 22642
[2025-01-15 00:29:28 +0000] [22645] [INFO] Booting worker with pid: 22645
[2025-01-15 00:30:55 +0000] [22637] [CRITICAL] WORKER TIMEOUT (pid:22642)
[2025-01-15 00:31:00 +0000] [22637] [ERROR] Worker (pid:22642) was sent SIGKILL! Perhaps out of memory?
[2025-01-15 00:31:00 +0000] [22656] [INFO] Booting worker with pid: 22656
[2025-01-15 00:35:34 +0000] [22637] [INFO] Handling signal: term
[2025-01-15 00:35:38 +0000] [22639] [INFO] Worker exiting (pid: 22639)
[2025-01-15 00:35:38 +0000] [22645] [INFO] Worker exiting (pid: 22645)
[2025-01-15 00:35:38 +0000] [22640] [INFO] Worker exiting (pid: 22640)
[2025-01-15 00:36:08 +0000] [22637] [ERROR] Worker (pid:22639) was sent SIGKILL! Perhaps out of memory?
[2025-01-15 00:36:08 +0000] [22637] [INFO] Shutting down: Master
[2025-01-15 00:36:08 +0000] [22637] [ERROR] Worker (pid:22640) was sent SIGKILL! Perhaps out of memory?
[2025-01-15 00:36:08 +0000] [22637] [ERROR] Worker (pid:22645) was sent SIGKILL! Perhaps out of memory?
[2025-01-15 00:36:08 +0000] [22637] [ERROR] Worker (pid:22656) was sent SIGKILL! Perhaps out of memory?
[2025-01-15 01:16:14 +0000] [26569] [INFO] Starting gunicorn 23.0.0
[2025-01-15 01:16:14 +0000] [26569] [INFO] Listening at: http://127.0.0.1:8000 (26569)
[2025-01-15 01:16:14 +0000] [26569] [INFO] Using worker: sync
[2025-01-15 01:16:14 +0000] [26571] [INFO] Booting worker with pid: 26571
[2025-01-15 01:16:14 +0000] [26572] [INFO] Booting worker with pid: 26572
[2025-01-15 01:16:15 +0000] [26575] [INFO] Booting worker with pid: 26575
[2025-01-15 01:16:15 +0000] [26576] [INFO] Booting worker with pid: 26576
[2025-01-15 02:40:24 +0000] [3188] [INFO] Starting gunicorn 23.0.0
[2025-01-15 02:40:24 +0000] [3188] [INFO] Listening at: http://127.0.0.1:8000 (3188)
[2025-01-15 02:40:24 +0000] [3188] [INFO] Using worker: sync
[2025-01-15 02:40:24 +0000] [3190] [INFO] Booting worker with pid: 3190
[2025-01-15 02:40:24 +0000] [3193] [INFO] Booting worker with pid: 3193
[2025-01-15 02:40:25 +0000] [3210] [INFO] Booting worker with pid: 3210
[2025-01-15 02:40:25 +0000] [3213] [INFO] Booting worker with pid: 3213
[2025-01-15 02:40:26 +0000] [3193] [ERROR] Exception in worker process
Traceback (most recent call last):
  File "/home/ec2-user/flask_miniproject1/.venv/lib64/python3.12/site-packages/gunicorn/arbiter.py", line 608, in spawn_worker
    worker.init_process()
  File "/home/ec2-user/flask_miniproject1/.venv/lib64/python3.12/site-packages/gunicorn/workers/base.py", line 135, in init_process
    self.load_wsgi()
  File "/home/ec2-user/flask_miniproject1/.venv/lib64/python3.12/site-packages/gunicorn/workers/base.py", line 147, in load_wsgi
    self.wsgi = self.app.wsgi()
                ^^^^^^^^^^^^^^^
  File "/home/ec2-user/flask_miniproject1/.venv/lib64/python3.12/site-packages/gunicorn/app/base.py", line 66, in wsgi
    self.callable = self.load()
                    ^^^^^^^^^^^
  File "/home/ec2-user/flask_miniproject1/.venv/lib64/python3.12/site-packages/gunicorn/app/wsgiapp.py", line 57, in load
    return self.load_wsgiapp()
           ^^^^^^^^^^^^^^^^^^^
  File "/home/ec2-user/flask_miniproject1/.venv/lib64/python3.12/site-packages/gunicorn/app/wsgiapp.py", line 47, in load_wsgiapp
    return util.import_app(self.app_uri)
           ^^^^^^^^^^^^^^^^^^^^^^^^^^^^^
  File "/home/ec2-user/flask_miniproject1/.venv/lib64/python3.12/site-packages/gunicorn/util.py", line 370, in import_app
    mod = importlib.import_module(module)
          ^^^^^^^^^^^^^^^^^^^^^^^^^^^^^^^
  File "/usr/lib64/python3.12/importlib/__init__.py", line 90, in import_module
    return _bootstrap._gcd_import(name[level:], package, level)
           ^^^^^^^^^^^^^^^^^^^^^^^^^^^^^^^^^^^^^^^^^^^^^^^^^^^^
  File "<frozen importlib._bootstrap>", line 1387, in _gcd_import
  File "<frozen importlib._bootstrap>", line 1360, in _find_and_load
  File "<frozen importlib._bootstrap>", line 1331, in _find_and_load_unlocked
  File "<frozen importlib._bootstrap>", line 935, in _load_unlocked
  File "<frozen importlib._bootstrap_external>", line 995, in exec_module
  File "<frozen importlib._bootstrap>", line 488, in _call_with_frames_removed
  File "/home/ec2-user/flask_miniproject1/wsgi.py", line 3, in <module>
    app = create_app()
          ^^^^^^^^^^^^
  File "/home/ec2-user/flask_miniproject1/app/__init__.py", line 34, in create_app
    from .routes.answers import answer_blp
  File "/home/ec2-user/flask_miniproject1/app/routes/answers.py", line 21
    if user_id and choice_id:
IndentationError: unexpected indent
[2025-01-15 02:40:26 +0000] [3193] [INFO] Worker exiting (pid: 3193)
[2025-01-15 02:40:26 +0000] [3210] [ERROR] Exception in worker process
Traceback (most recent call last):
  File "/home/ec2-user/flask_miniproject1/.venv/lib64/python3.12/site-packages/gunicorn/arbiter.py", line 608, in spawn_worker
    worker.init_process()
  File "/home/ec2-user/flask_miniproject1/.venv/lib64/python3.12/site-packages/gunicorn/workers/base.py", line 135, in init_process
    self.load_wsgi()
  File "/home/ec2-user/flask_miniproject1/.venv/lib64/python3.12/site-packages/gunicorn/workers/base.py", line 147, in load_wsgi
    self.wsgi = self.app.wsgi()
                ^^^^^^^^^^^^^^^
  File "/home/ec2-user/flask_miniproject1/.venv/lib64/python3.12/site-packages/gunicorn/app/base.py", line 66, in wsgi
    self.callable = self.load()
                    ^^^^^^^^^^^
  File "/home/ec2-user/flask_miniproject1/.venv/lib64/python3.12/site-packages/gunicorn/app/wsgiapp.py", line 57, in load
    return self.load_wsgiapp()
           ^^^^^^^^^^^^^^^^^^^
  File "/home/ec2-user/flask_miniproject1/.venv/lib64/python3.12/site-packages/gunicorn/app/wsgiapp.py", line 47, in load_wsgiapp
    return util.import_app(self.app_uri)
           ^^^^^^^^^^^^^^^^^^^^^^^^^^^^^
  File "/home/ec2-user/flask_miniproject1/.venv/lib64/python3.12/site-packages/gunicorn/util.py", line 370, in import_app
    mod = importlib.import_module(module)
          ^^^^^^^^^^^^^^^^^^^^^^^^^^^^^^^
  File "/usr/lib64/python3.12/importlib/__init__.py", line 90, in import_module
    return _bootstrap._gcd_import(name[level:], package, level)
           ^^^^^^^^^^^^^^^^^^^^^^^^^^^^^^^^^^^^^^^^^^^^^^^^^^^^
  File "<frozen importlib._bootstrap>", line 1387, in _gcd_import
  File "<frozen importlib._bootstrap>", line 1360, in _find_and_load
  File "<frozen importlib._bootstrap>", line 1331, in _find_and_load_unlocked
  File "<frozen importlib._bootstrap>", line 935, in _load_unlocked
  File "<frozen importlib._bootstrap_external>", line 995, in exec_module
  File "<frozen importlib._bootstrap>", line 488, in _call_with_frames_removed
  File "/home/ec2-user/flask_miniproject1/wsgi.py", line 3, in <module>
    app = create_app()
          ^^^^^^^^^^^^
  File "/home/ec2-user/flask_miniproject1/app/__init__.py", line 34, in create_app
    from .routes.answers import answer_blp
  File "/home/ec2-user/flask_miniproject1/app/routes/answers.py", line 21
    if user_id and choice_id:
IndentationError: unexpected indent
[2025-01-15 02:40:26 +0000] [3210] [INFO] Worker exiting (pid: 3210)
[2025-01-15 02:40:26 +0000] [3190] [ERROR] Exception in worker process
Traceback (most recent call last):
  File "/home/ec2-user/flask_miniproject1/.venv/lib64/python3.12/site-packages/gunicorn/arbiter.py", line 608, in spawn_worker
    worker.init_process()
  File "/home/ec2-user/flask_miniproject1/.venv/lib64/python3.12/site-packages/gunicorn/workers/base.py", line 135, in init_process
    self.load_wsgi()
  File "/home/ec2-user/flask_miniproject1/.venv/lib64/python3.12/site-packages/gunicorn/workers/base.py", line 147, in load_wsgi
    self.wsgi = self.app.wsgi()
                ^^^^^^^^^^^^^^^
  File "/home/ec2-user/flask_miniproject1/.venv/lib64/python3.12/site-packages/gunicorn/app/base.py", line 66, in wsgi
    self.callable = self.load()
                    ^^^^^^^^^^^
  File "/home/ec2-user/flask_miniproject1/.venv/lib64/python3.12/site-packages/gunicorn/app/wsgiapp.py", line 57, in load
    return self.load_wsgiapp()
           ^^^^^^^^^^^^^^^^^^^
  File "/home/ec2-user/flask_miniproject1/.venv/lib64/python3.12/site-packages/gunicorn/app/wsgiapp.py", line 47, in load_wsgiapp
    return util.import_app(self.app_uri)
           ^^^^^^^^^^^^^^^^^^^^^^^^^^^^^
  File "/home/ec2-user/flask_miniproject1/.venv/lib64/python3.12/site-packages/gunicorn/util.py", line 370, in import_app
    mod = importlib.import_module(module)
          ^^^^^^^^^^^^^^^^^^^^^^^^^^^^^^^
  File "/usr/lib64/python3.12/importlib/__init__.py", line 90, in import_module
    return _bootstrap._gcd_import(name[level:], package, level)
           ^^^^^^^^^^^^^^^^^^^^^^^^^^^^^^^^^^^^^^^^^^^^^^^^^^^^
  File "<frozen importlib._bootstrap>", line 1387, in _gcd_import
  File "<frozen importlib._bootstrap>", line 1360, in _find_and_load
  File "<frozen importlib._bootstrap>", line 1331, in _find_and_load_unlocked
  File "<frozen importlib._bootstrap>", line 935, in _load_unlocked
  File "<frozen importlib._bootstrap_external>", line 995, in exec_module
  File "<frozen importlib._bootstrap>", line 488, in _call_with_frames_removed
  File "/home/ec2-user/flask_miniproject1/wsgi.py", line 3, in <module>
    app = create_app()
          ^^^^^^^^^^^^
  File "/home/ec2-user/flask_miniproject1/app/__init__.py", line 34, in create_app
    from .routes.answers import answer_blp
  File "/home/ec2-user/flask_miniproject1/app/routes/answers.py", line 21
    if user_id and choice_id:
IndentationError: unexpected indent
[2025-01-15 02:40:26 +0000] [3190] [INFO] Worker exiting (pid: 3190)
[2025-01-15 02:40:26 +0000] [3213] [ERROR] Exception in worker process
Traceback (most recent call last):
  File "/home/ec2-user/flask_miniproject1/.venv/lib64/python3.12/site-packages/gunicorn/arbiter.py", line 608, in spawn_worker
    worker.init_process()
  File "/home/ec2-user/flask_miniproject1/.venv/lib64/python3.12/site-packages/gunicorn/workers/base.py", line 135, in init_process
    self.load_wsgi()
  File "/home/ec2-user/flask_miniproject1/.venv/lib64/python3.12/site-packages/gunicorn/workers/base.py", line 147, in load_wsgi
    self.wsgi = self.app.wsgi()
                ^^^^^^^^^^^^^^^
  File "/home/ec2-user/flask_miniproject1/.venv/lib64/python3.12/site-packages/gunicorn/app/base.py", line 66, in wsgi
    self.callable = self.load()
                    ^^^^^^^^^^^
  File "/home/ec2-user/flask_miniproject1/.venv/lib64/python3.12/site-packages/gunicorn/app/wsgiapp.py", line 57, in load
    return self.load_wsgiapp()
           ^^^^^^^^^^^^^^^^^^^
  File "/home/ec2-user/flask_miniproject1/.venv/lib64/python3.12/site-packages/gunicorn/app/wsgiapp.py", line 47, in load_wsgiapp
    return util.import_app(self.app_uri)
           ^^^^^^^^^^^^^^^^^^^^^^^^^^^^^
  File "/home/ec2-user/flask_miniproject1/.venv/lib64/python3.12/site-packages/gunicorn/util.py", line 370, in import_app
    mod = importlib.import_module(module)
          ^^^^^^^^^^^^^^^^^^^^^^^^^^^^^^^
  File "/usr/lib64/python3.12/importlib/__init__.py", line 90, in import_module
    return _bootstrap._gcd_import(name[level:], package, level)
           ^^^^^^^^^^^^^^^^^^^^^^^^^^^^^^^^^^^^^^^^^^^^^^^^^^^^
  File "<frozen importlib._bootstrap>", line 1387, in _gcd_import
  File "<frozen importlib._bootstrap>", line 1360, in _find_and_load
  File "<frozen importlib._bootstrap>", line 1331, in _find_and_load_unlocked
  File "<frozen importlib._bootstrap>", line 935, in _load_unlocked
  File "<frozen importlib._bootstrap_external>", line 995, in exec_module
  File "<frozen importlib._bootstrap>", line 488, in _call_with_frames_removed
  File "/home/ec2-user/flask_miniproject1/wsgi.py", line 3, in <module>
    app = create_app()
          ^^^^^^^^^^^^
  File "/home/ec2-user/flask_miniproject1/app/__init__.py", line 34, in create_app
    from .routes.answers import answer_blp
  File "/home/ec2-user/flask_miniproject1/app/routes/answers.py", line 21
    if user_id and choice_id:
IndentationError: unexpected indent
[2025-01-15 02:40:26 +0000] [3213] [INFO] Worker exiting (pid: 3213)
[2025-01-15 02:40:27 +0000] [3188] [ERROR] Worker (pid:3213) exited with code 3
[2025-01-15 02:40:27 +0000] [3188] [ERROR] Worker (pid:3210) was sent SIGTERM!
[2025-01-15 02:40:27 +0000] [3188] [ERROR] Worker (pid:3190) exited with code 3
[2025-01-15 02:40:27 +0000] [3188] [ERROR] Worker (pid:3193) exited with code 3
[2025-01-15 02:42:38 +0000] [4264] [INFO] Starting gunicorn 23.0.0
[2025-01-15 02:42:38 +0000] [4264] [INFO] Listening at: http://127.0.0.1:8000 (4264)
[2025-01-15 02:42:38 +0000] [4264] [INFO] Using worker: sync
[2025-01-15 02:42:38 +0000] [4266] [INFO] Booting worker with pid: 4266
[2025-01-15 02:42:38 +0000] [4269] [INFO] Booting worker with pid: 4269
[2025-01-15 02:42:38 +0000] [4270] [INFO] Booting worker with pid: 4270
[2025-01-15 02:42:39 +0000] [4271] [INFO] Booting worker with pid: 4271
[2025-01-15 02:54:35,167] ERROR in app: Exception on /choice/1 [GET]
Traceback (most recent call last):
  File "/home/ec2-user/flask_miniproject1/.venv/lib64/python3.12/site-packages/flask/app.py", line 1511, in wsgi_app
    response = self.full_dispatch_request()
               ^^^^^^^^^^^^^^^^^^^^^^^^^^^^
  File "/home/ec2-user/flask_miniproject1/.venv/lib64/python3.12/site-packages/flask/app.py", line 919, in full_dispatch_request
    rv = self.handle_user_exception(e)
         ^^^^^^^^^^^^^^^^^^^^^^^^^^^^^
  File "/home/ec2-user/flask_miniproject1/.venv/lib64/python3.12/site-packages/flask/app.py", line 917, in full_dispatch_request
    rv = self.dispatch_request()
         ^^^^^^^^^^^^^^^^^^^^^^^
  File "/home/ec2-user/flask_miniproject1/.venv/lib64/python3.12/site-packages/flask/app.py", line 902, in dispatch_request
    return self.ensure_sync(self.view_functions[rule.endpoint])(**view_args)  # type: ignore[no-any-return]
           ^^^^^^^^^^^^^^^^^^^^^^^^^^^^^^^^^^^^^^^^^^^^^^^^^^^^^^^^^^^^^^^^^
  File "/home/ec2-user/flask_miniproject1/.venv/lib64/python3.12/site-packages/flask/views.py", line 110, in view
    return current_app.ensure_sync(self.dispatch_request)(**kwargs)  # type: ignore[no-any-return]
           ^^^^^^^^^^^^^^^^^^^^^^^^^^^^^^^^^^^^^^^^^^^^^^^^^^^^^^^^
  File "/home/ec2-user/flask_miniproject1/.venv/lib64/python3.12/site-packages/flask/views.py", line 191, in dispatch_request
    return current_app.ensure_sync(meth)(**kwargs)  # type: ignore[no-any-return]
           ^^^^^^^^^^^^^^^^^^^^^^^^^^^^^^^^^^^^^^^
  File "/home/ec2-user/flask_miniproject1/app/routes/choices.py", line 37, in get
    return {"choices":[{"id":choice.id,"content":choice.content,"is_active":choice.is_active,"sqe":choice.sqe}for choice in choices]}
                                                                                                                            ^^^^^^^
TypeError: 'Choices' object is not iterable
[2025-01-15 02:54:59 +0000] [4264] [INFO] Handling signal: term
[2025-01-15 02:54:59 +0000] [4269] [INFO] Worker exiting (pid: 4269)
[2025-01-15 02:54:59 +0000] [4270] [INFO] Worker exiting (pid: 4270)
[2025-01-15 02:54:59 +0000] [4271] [INFO] Worker exiting (pid: 4271)
[2025-01-15 02:54:59 +0000] [4266] [INFO] Worker exiting (pid: 4266)
[2025-01-15 02:54:59 +0000] [4264] [ERROR] Worker (pid:4266) was sent SIGTERM!
[2025-01-15 02:54:59 +0000] [4264] [ERROR] Worker (pid:4269) was sent SIGTERM!
[2025-01-15 02:54:59 +0000] [4264] [ERROR] Worker (pid:4270) was sent SIGTERM!
[2025-01-15 02:54:59 +0000] [4264] [ERROR] Worker (pid:4271) was sent SIGTERM!
[2025-01-15 02:54:59 +0000] [4264] [INFO] Shutting down: Master
[2025-01-15 02:55:04 +0000] [7424] [INFO] Starting gunicorn 23.0.0
[2025-01-15 02:55:04 +0000] [7424] [INFO] Listening at: http://127.0.0.1:8000 (7424)
[2025-01-15 02:55:04 +0000] [7424] [INFO] Using worker: sync
[2025-01-15 02:55:04 +0000] [7426] [INFO] Booting worker with pid: 7426
[2025-01-15 02:55:04 +0000] [7427] [INFO] Booting worker with pid: 7427
[2025-01-15 02:55:04 +0000] [7428] [INFO] Booting worker with pid: 7428
[2025-01-15 02:55:04 +0000] [7431] [INFO] Booting worker with pid: 7431
[2025-01-15 02:55:21,930] ERROR in app: Exception on /choice/1 [GET]
Traceback (most recent call last):
  File "/home/ec2-user/flask_miniproject1/.venv/lib64/python3.12/site-packages/flask/app.py", line 1511, in wsgi_app
    response = self.full_dispatch_request()
               ^^^^^^^^^^^^^^^^^^^^^^^^^^^^
  File "/home/ec2-user/flask_miniproject1/.venv/lib64/python3.12/site-packages/flask/app.py", line 919, in full_dispatch_request
    rv = self.handle_user_exception(e)
         ^^^^^^^^^^^^^^^^^^^^^^^^^^^^^
  File "/home/ec2-user/flask_miniproject1/.venv/lib64/python3.12/site-packages/flask/app.py", line 917, in full_dispatch_request
    rv = self.dispatch_request()
         ^^^^^^^^^^^^^^^^^^^^^^^
  File "/home/ec2-user/flask_miniproject1/.venv/lib64/python3.12/site-packages/flask/app.py", line 902, in dispatch_request
    return self.ensure_sync(self.view_functions[rule.endpoint])(**view_args)  # type: ignore[no-any-return]
           ^^^^^^^^^^^^^^^^^^^^^^^^^^^^^^^^^^^^^^^^^^^^^^^^^^^^^^^^^^^^^^^^^
  File "/home/ec2-user/flask_miniproject1/.venv/lib64/python3.12/site-packages/flask/views.py", line 110, in view
    return current_app.ensure_sync(self.dispatch_request)(**kwargs)  # type: ignore[no-any-return]
           ^^^^^^^^^^^^^^^^^^^^^^^^^^^^^^^^^^^^^^^^^^^^^^^^^^^^^^^^
  File "/home/ec2-user/flask_miniproject1/.venv/lib64/python3.12/site-packages/flask/views.py", line 191, in dispatch_request
    return current_app.ensure_sync(meth)(**kwargs)  # type: ignore[no-any-return]
           ^^^^^^^^^^^^^^^^^^^^^^^^^^^^^^^^^^^^^^^
  File "/home/ec2-user/flask_miniproject1/app/routes/choices.py", line 37, in get
    return {"choices":[{"id":choice.id,"content":choice.content,"is_active":choice.is_active,"sqe":choice.sqe}for choice in choices]}
                                                                                                                            ^^^^^^^
TypeError: 'Choices' object is not iterable
[2025-01-15 02:57:10,298] ERROR in app: Exception on /choice/1 [GET]
Traceback (most recent call last):
  File "/home/ec2-user/flask_miniproject1/.venv/lib64/python3.12/site-packages/flask/app.py", line 1511, in wsgi_app
    response = self.full_dispatch_request()
               ^^^^^^^^^^^^^^^^^^^^^^^^^^^^
  File "/home/ec2-user/flask_miniproject1/.venv/lib64/python3.12/site-packages/flask/app.py", line 919, in full_dispatch_request
    rv = self.handle_user_exception(e)
         ^^^^^^^^^^^^^^^^^^^^^^^^^^^^^
  File "/home/ec2-user/flask_miniproject1/.venv/lib64/python3.12/site-packages/flask/app.py", line 917, in full_dispatch_request
    rv = self.dispatch_request()
         ^^^^^^^^^^^^^^^^^^^^^^^
  File "/home/ec2-user/flask_miniproject1/.venv/lib64/python3.12/site-packages/flask/app.py", line 902, in dispatch_request
    return self.ensure_sync(self.view_functions[rule.endpoint])(**view_args)  # type: ignore[no-any-return]
           ^^^^^^^^^^^^^^^^^^^^^^^^^^^^^^^^^^^^^^^^^^^^^^^^^^^^^^^^^^^^^^^^^
  File "/home/ec2-user/flask_miniproject1/.venv/lib64/python3.12/site-packages/flask/views.py", line 110, in view
    return current_app.ensure_sync(self.dispatch_request)(**kwargs)  # type: ignore[no-any-return]
           ^^^^^^^^^^^^^^^^^^^^^^^^^^^^^^^^^^^^^^^^^^^^^^^^^^^^^^^^
  File "/home/ec2-user/flask_miniproject1/.venv/lib64/python3.12/site-packages/flask/views.py", line 191, in dispatch_request
    return current_app.ensure_sync(meth)(**kwargs)  # type: ignore[no-any-return]
           ^^^^^^^^^^^^^^^^^^^^^^^^^^^^^^^^^^^^^^^
  File "/home/ec2-user/flask_miniproject1/app/routes/choices.py", line 37, in get
    return {"choices":[{"id":choice.id,"content":choice.content,"is_active":choice.is_active,"sqe":choice.sqe}for choice in choices]}
                                                                                                                            ^^^^^^^
TypeError: 'Choices' object is not iterable
[2025-01-15 02:57:53,390] ERROR in app: Exception on /choice/1 [GET]
Traceback (most recent call last):
  File "/home/ec2-user/flask_miniproject1/.venv/lib64/python3.12/site-packages/flask/app.py", line 1511, in wsgi_app
    response = self.full_dispatch_request()
               ^^^^^^^^^^^^^^^^^^^^^^^^^^^^
  File "/home/ec2-user/flask_miniproject1/.venv/lib64/python3.12/site-packages/flask/app.py", line 919, in full_dispatch_request
    rv = self.handle_user_exception(e)
         ^^^^^^^^^^^^^^^^^^^^^^^^^^^^^
  File "/home/ec2-user/flask_miniproject1/.venv/lib64/python3.12/site-packages/flask/app.py", line 917, in full_dispatch_request
    rv = self.dispatch_request()
         ^^^^^^^^^^^^^^^^^^^^^^^
  File "/home/ec2-user/flask_miniproject1/.venv/lib64/python3.12/site-packages/flask/app.py", line 902, in dispatch_request
    return self.ensure_sync(self.view_functions[rule.endpoint])(**view_args)  # type: ignore[no-any-return]
           ^^^^^^^^^^^^^^^^^^^^^^^^^^^^^^^^^^^^^^^^^^^^^^^^^^^^^^^^^^^^^^^^^
  File "/home/ec2-user/flask_miniproject1/.venv/lib64/python3.12/site-packages/flask/views.py", line 110, in view
    return current_app.ensure_sync(self.dispatch_request)(**kwargs)  # type: ignore[no-any-return]
           ^^^^^^^^^^^^^^^^^^^^^^^^^^^^^^^^^^^^^^^^^^^^^^^^^^^^^^^^
  File "/home/ec2-user/flask_miniproject1/.venv/lib64/python3.12/site-packages/flask/views.py", line 191, in dispatch_request
    return current_app.ensure_sync(meth)(**kwargs)  # type: ignore[no-any-return]
           ^^^^^^^^^^^^^^^^^^^^^^^^^^^^^^^^^^^^^^^
  File "/home/ec2-user/flask_miniproject1/app/routes/choices.py", line 37, in get
    return {"choices":[{"id":choice.id,"content":choice.content,"is_active":choice.is_active,"sqe":choice.sqe}for choice in choices]}
                                                                                                                            ^^^^^^^
TypeError: 'Choices' object is not iterable
[2025-01-15 02:58:23 +0000] [7424] [INFO] Handling signal: term
[2025-01-15 02:58:23 +0000] [7426] [INFO] Worker exiting (pid: 7426)
[2025-01-15 02:58:23 +0000] [7427] [INFO] Worker exiting (pid: 7427)
[2025-01-15 02:58:23 +0000] [7428] [INFO] Worker exiting (pid: 7428)
[2025-01-15 02:58:23 +0000] [7431] [INFO] Worker exiting (pid: 7431)
[2025-01-15 02:58:24 +0000] [7424] [ERROR] Worker (pid:7426) was sent SIGTERM!
[2025-01-15 02:58:24 +0000] [7424] [ERROR] Worker (pid:7427) was sent SIGTERM!
[2025-01-15 02:58:24 +0000] [7424] [INFO] Shutting down: Master
[2025-01-15 02:58:26 +0000] [8681] [INFO] Starting gunicorn 23.0.0
[2025-01-15 02:58:26 +0000] [8681] [INFO] Listening at: http://127.0.0.1:8000 (8681)
[2025-01-15 02:58:26 +0000] [8681] [INFO] Using worker: sync
[2025-01-15 02:58:26 +0000] [8683] [INFO] Booting worker with pid: 8683
[2025-01-15 02:58:26 +0000] [8684] [INFO] Booting worker with pid: 8684
[2025-01-15 02:58:26 +0000] [8687] [INFO] Booting worker with pid: 8687
[2025-01-15 02:58:26 +0000] [8688] [INFO] Booting worker with pid: 8688
[2025-01-15 02:58:31,020] ERROR in app: Exception on /choice/1 [GET]
Traceback (most recent call last):
  File "/home/ec2-user/flask_miniproject1/.venv/lib64/python3.12/site-packages/flask/app.py", line 1511, in wsgi_app
    response = self.full_dispatch_request()
               ^^^^^^^^^^^^^^^^^^^^^^^^^^^^
  File "/home/ec2-user/flask_miniproject1/.venv/lib64/python3.12/site-packages/flask/app.py", line 919, in full_dispatch_request
    rv = self.handle_user_exception(e)
         ^^^^^^^^^^^^^^^^^^^^^^^^^^^^^
  File "/home/ec2-user/flask_miniproject1/.venv/lib64/python3.12/site-packages/flask/app.py", line 917, in full_dispatch_request
    rv = self.dispatch_request()
         ^^^^^^^^^^^^^^^^^^^^^^^
  File "/home/ec2-user/flask_miniproject1/.venv/lib64/python3.12/site-packages/flask/app.py", line 902, in dispatch_request
    return self.ensure_sync(self.view_functions[rule.endpoint])(**view_args)  # type: ignore[no-any-return]
           ^^^^^^^^^^^^^^^^^^^^^^^^^^^^^^^^^^^^^^^^^^^^^^^^^^^^^^^^^^^^^^^^^
  File "/home/ec2-user/flask_miniproject1/.venv/lib64/python3.12/site-packages/flask/views.py", line 110, in view
    return current_app.ensure_sync(self.dispatch_request)(**kwargs)  # type: ignore[no-any-return]
           ^^^^^^^^^^^^^^^^^^^^^^^^^^^^^^^^^^^^^^^^^^^^^^^^^^^^^^^^
  File "/home/ec2-user/flask_miniproject1/.venv/lib64/python3.12/site-packages/flask/views.py", line 191, in dispatch_request
    return current_app.ensure_sync(meth)(**kwargs)  # type: ignore[no-any-return]
           ^^^^^^^^^^^^^^^^^^^^^^^^^^^^^^^^^^^^^^^
  File "/home/ec2-user/flask_miniproject1/app/routes/choices.py", line 36, in get
    choices = Choices.query.get_or_404(question_id=question_id)
              ^^^^^^^^^^^^^^^^^^^^^^^^^^^^^^^^^^^^^^^^^^^^^^^^^
TypeError: Query.get_or_404() got an unexpected keyword argument 'question_id'
[2025-01-15 02:59:53 +0000] [8681] [INFO] Handling signal: term
[2025-01-15 02:59:53 +0000] [8683] [INFO] Worker exiting (pid: 8683)
[2025-01-15 02:59:53 +0000] [8684] [INFO] Worker exiting (pid: 8684)
[2025-01-15 02:59:53 +0000] [8687] [INFO] Worker exiting (pid: 8687)
[2025-01-15 02:59:53 +0000] [8688] [INFO] Worker exiting (pid: 8688)
[2025-01-15 02:59:53 +0000] [8681] [ERROR] Worker (pid:8683) was sent SIGTERM!
[2025-01-15 02:59:53 +0000] [8681] [ERROR] Worker (pid:8684) was sent SIGTERM!
[2025-01-15 02:59:53 +0000] [8681] [INFO] Shutting down: Master
[2025-01-15 02:59:56 +0000] [9474] [INFO] Starting gunicorn 23.0.0
[2025-01-15 02:59:56 +0000] [9474] [INFO] Listening at: http://127.0.0.1:8000 (9474)
[2025-01-15 02:59:56 +0000] [9474] [INFO] Using worker: sync
[2025-01-15 02:59:56 +0000] [9476] [INFO] Booting worker with pid: 9476
[2025-01-15 02:59:56 +0000] [9477] [INFO] Booting worker with pid: 9477
[2025-01-15 02:59:56 +0000] [9478] [INFO] Booting worker with pid: 9478
[2025-01-15 02:59:56 +0000] [9481] [INFO] Booting worker with pid: 9481
[2025-01-15 03:00:01,985] ERROR in app: Exception on /choice/1 [GET]
Traceback (most recent call last):
  File "/home/ec2-user/flask_miniproject1/.venv/lib64/python3.12/site-packages/flask/app.py", line 1511, in wsgi_app
    response = self.full_dispatch_request()
               ^^^^^^^^^^^^^^^^^^^^^^^^^^^^
  File "/home/ec2-user/flask_miniproject1/.venv/lib64/python3.12/site-packages/flask/app.py", line 919, in full_dispatch_request
    rv = self.handle_user_exception(e)
         ^^^^^^^^^^^^^^^^^^^^^^^^^^^^^
  File "/home/ec2-user/flask_miniproject1/.venv/lib64/python3.12/site-packages/flask/app.py", line 917, in full_dispatch_request
    rv = self.dispatch_request()
         ^^^^^^^^^^^^^^^^^^^^^^^
  File "/home/ec2-user/flask_miniproject1/.venv/lib64/python3.12/site-packages/flask/app.py", line 902, in dispatch_request
    return self.ensure_sync(self.view_functions[rule.endpoint])(**view_args)  # type: ignore[no-any-return]
           ^^^^^^^^^^^^^^^^^^^^^^^^^^^^^^^^^^^^^^^^^^^^^^^^^^^^^^^^^^^^^^^^^
  File "/home/ec2-user/flask_miniproject1/.venv/lib64/python3.12/site-packages/flask/views.py", line 110, in view
    return current_app.ensure_sync(self.dispatch_request)(**kwargs)  # type: ignore[no-any-return]
           ^^^^^^^^^^^^^^^^^^^^^^^^^^^^^^^^^^^^^^^^^^^^^^^^^^^^^^^^
  File "/home/ec2-user/flask_miniproject1/.venv/lib64/python3.12/site-packages/flask/views.py", line 191, in dispatch_request
    return current_app.ensure_sync(meth)(**kwargs)  # type: ignore[no-any-return]
           ^^^^^^^^^^^^^^^^^^^^^^^^^^^^^^^^^^^^^^^
  File "/home/ec2-user/flask_miniproject1/app/routes/choices.py", line 36, in get
    choices = Choices.query.get_or_404(question_id=question_id).all()
              ^^^^^^^^^^^^^^^^^^^^^^^^^^^^^^^^^^^^^^^^^^^^^^^^^
TypeError: Query.get_or_404() got an unexpected keyword argument 'question_id'
[2025-01-15 03:02:32 +0000] [9474] [INFO] Handling signal: term
[2025-01-15 03:02:32 +0000] [9476] [INFO] Worker exiting (pid: 9476)
[2025-01-15 03:02:32 +0000] [9477] [INFO] Worker exiting (pid: 9477)
[2025-01-15 03:02:32 +0000] [9478] [INFO] Worker exiting (pid: 9478)
[2025-01-15 03:02:32 +0000] [9481] [INFO] Worker exiting (pid: 9481)
[2025-01-15 03:02:32 +0000] [9474] [ERROR] Worker (pid:9476) was sent SIGTERM!
[2025-01-15 03:02:32 +0000] [9474] [ERROR] Worker (pid:9477) was sent SIGTERM!
[2025-01-15 03:02:33 +0000] [9474] [ERROR] Worker (pid:9478) was sent SIGTERM!
[2025-01-15 03:02:33 +0000] [9474] [ERROR] Worker (pid:9481) was sent SIGTERM!
[2025-01-15 03:02:33 +0000] [9474] [INFO] Shutting down: Master
[2025-01-15 03:02:37 +0000] [10487] [INFO] Starting gunicorn 23.0.0
[2025-01-15 03:02:37 +0000] [10487] [INFO] Listening at: http://127.0.0.1:8000 (10487)
[2025-01-15 03:02:37 +0000] [10487] [INFO] Using worker: sync
[2025-01-15 03:02:37 +0000] [10489] [INFO] Booting worker with pid: 10489
[2025-01-15 03:02:37 +0000] [10492] [INFO] Booting worker with pid: 10492
[2025-01-15 03:02:38 +0000] [10493] [INFO] Booting worker with pid: 10493
[2025-01-15 03:02:38 +0000] [10494] [INFO] Booting worker with pid: 10494
[2025-01-15 03:02:40,645] ERROR in app: Exception on /choice/1 [GET]
Traceback (most recent call last):
  File "/home/ec2-user/flask_miniproject1/.venv/lib64/python3.12/site-packages/flask/app.py", line 1511, in wsgi_app
    response = self.full_dispatch_request()
               ^^^^^^^^^^^^^^^^^^^^^^^^^^^^
  File "/home/ec2-user/flask_miniproject1/.venv/lib64/python3.12/site-packages/flask/app.py", line 919, in full_dispatch_request
    rv = self.handle_user_exception(e)
         ^^^^^^^^^^^^^^^^^^^^^^^^^^^^^
  File "/home/ec2-user/flask_miniproject1/.venv/lib64/python3.12/site-packages/flask/app.py", line 917, in full_dispatch_request
    rv = self.dispatch_request()
         ^^^^^^^^^^^^^^^^^^^^^^^
  File "/home/ec2-user/flask_miniproject1/.venv/lib64/python3.12/site-packages/flask/app.py", line 902, in dispatch_request
    return self.ensure_sync(self.view_functions[rule.endpoint])(**view_args)  # type: ignore[no-any-return]
           ^^^^^^^^^^^^^^^^^^^^^^^^^^^^^^^^^^^^^^^^^^^^^^^^^^^^^^^^^^^^^^^^^
  File "/home/ec2-user/flask_miniproject1/.venv/lib64/python3.12/site-packages/flask/views.py", line 110, in view
    return current_app.ensure_sync(self.dispatch_request)(**kwargs)  # type: ignore[no-any-return]
           ^^^^^^^^^^^^^^^^^^^^^^^^^^^^^^^^^^^^^^^^^^^^^^^^^^^^^^^^
  File "/home/ec2-user/flask_miniproject1/.venv/lib64/python3.12/site-packages/flask/views.py", line 191, in dispatch_request
    return current_app.ensure_sync(meth)(**kwargs)  # type: ignore[no-any-return]
           ^^^^^^^^^^^^^^^^^^^^^^^^^^^^^^^^^^^^^^^
  File "/home/ec2-user/flask_miniproject1/app/routes/choices.py", line 36, in get
    choices = Choices.filter_by(question_id=question_id).all()
              ^^^^^^^^^^^^^^^^^
AttributeError: type object 'Choices' has no attribute 'filter_by'
[2025-01-15 03:02:44,945] ERROR in app: Exception on /choice/1 [GET]
Traceback (most recent call last):
  File "/home/ec2-user/flask_miniproject1/.venv/lib64/python3.12/site-packages/flask/app.py", line 1511, in wsgi_app
    response = self.full_dispatch_request()
               ^^^^^^^^^^^^^^^^^^^^^^^^^^^^
  File "/home/ec2-user/flask_miniproject1/.venv/lib64/python3.12/site-packages/flask/app.py", line 919, in full_dispatch_request
    rv = self.handle_user_exception(e)
         ^^^^^^^^^^^^^^^^^^^^^^^^^^^^^
  File "/home/ec2-user/flask_miniproject1/.venv/lib64/python3.12/site-packages/flask/app.py", line 917, in full_dispatch_request
    rv = self.dispatch_request()
         ^^^^^^^^^^^^^^^^^^^^^^^
  File "/home/ec2-user/flask_miniproject1/.venv/lib64/python3.12/site-packages/flask/app.py", line 902, in dispatch_request
    return self.ensure_sync(self.view_functions[rule.endpoint])(**view_args)  # type: ignore[no-any-return]
           ^^^^^^^^^^^^^^^^^^^^^^^^^^^^^^^^^^^^^^^^^^^^^^^^^^^^^^^^^^^^^^^^^
  File "/home/ec2-user/flask_miniproject1/.venv/lib64/python3.12/site-packages/flask/views.py", line 110, in view
    return current_app.ensure_sync(self.dispatch_request)(**kwargs)  # type: ignore[no-any-return]
           ^^^^^^^^^^^^^^^^^^^^^^^^^^^^^^^^^^^^^^^^^^^^^^^^^^^^^^^^
  File "/home/ec2-user/flask_miniproject1/.venv/lib64/python3.12/site-packages/flask/views.py", line 191, in dispatch_request
    return current_app.ensure_sync(meth)(**kwargs)  # type: ignore[no-any-return]
           ^^^^^^^^^^^^^^^^^^^^^^^^^^^^^^^^^^^^^^^
  File "/home/ec2-user/flask_miniproject1/app/routes/choices.py", line 36, in get
    choices = Choices.filter_by(question_id=question_id).all()
              ^^^^^^^^^^^^^^^^^
AttributeError: type object 'Choices' has no attribute 'filter_by'
[2025-01-15 03:02:45,524] ERROR in app: Exception on /choice/1 [GET]
Traceback (most recent call last):
  File "/home/ec2-user/flask_miniproject1/.venv/lib64/python3.12/site-packages/flask/app.py", line 1511, in wsgi_app
    response = self.full_dispatch_request()
               ^^^^^^^^^^^^^^^^^^^^^^^^^^^^
  File "/home/ec2-user/flask_miniproject1/.venv/lib64/python3.12/site-packages/flask/app.py", line 919, in full_dispatch_request
    rv = self.handle_user_exception(e)
         ^^^^^^^^^^^^^^^^^^^^^^^^^^^^^
  File "/home/ec2-user/flask_miniproject1/.venv/lib64/python3.12/site-packages/flask/app.py", line 917, in full_dispatch_request
    rv = self.dispatch_request()
         ^^^^^^^^^^^^^^^^^^^^^^^
  File "/home/ec2-user/flask_miniproject1/.venv/lib64/python3.12/site-packages/flask/app.py", line 902, in dispatch_request
    return self.ensure_sync(self.view_functions[rule.endpoint])(**view_args)  # type: ignore[no-any-return]
           ^^^^^^^^^^^^^^^^^^^^^^^^^^^^^^^^^^^^^^^^^^^^^^^^^^^^^^^^^^^^^^^^^
  File "/home/ec2-user/flask_miniproject1/.venv/lib64/python3.12/site-packages/flask/views.py", line 110, in view
    return current_app.ensure_sync(self.dispatch_request)(**kwargs)  # type: ignore[no-any-return]
           ^^^^^^^^^^^^^^^^^^^^^^^^^^^^^^^^^^^^^^^^^^^^^^^^^^^^^^^^
  File "/home/ec2-user/flask_miniproject1/.venv/lib64/python3.12/site-packages/flask/views.py", line 191, in dispatch_request
    return current_app.ensure_sync(meth)(**kwargs)  # type: ignore[no-any-return]
           ^^^^^^^^^^^^^^^^^^^^^^^^^^^^^^^^^^^^^^^
  File "/home/ec2-user/flask_miniproject1/app/routes/choices.py", line 36, in get
    choices = Choices.filter_by(question_id=question_id).all()
              ^^^^^^^^^^^^^^^^^
AttributeError: type object 'Choices' has no attribute 'filter_by'
[2025-01-15 03:02:45,922] ERROR in app: Exception on /choice/1 [GET]
Traceback (most recent call last):
  File "/home/ec2-user/flask_miniproject1/.venv/lib64/python3.12/site-packages/flask/app.py", line 1511, in wsgi_app
    response = self.full_dispatch_request()
               ^^^^^^^^^^^^^^^^^^^^^^^^^^^^
  File "/home/ec2-user/flask_miniproject1/.venv/lib64/python3.12/site-packages/flask/app.py", line 919, in full_dispatch_request
    rv = self.handle_user_exception(e)
         ^^^^^^^^^^^^^^^^^^^^^^^^^^^^^
  File "/home/ec2-user/flask_miniproject1/.venv/lib64/python3.12/site-packages/flask/app.py", line 917, in full_dispatch_request
    rv = self.dispatch_request()
         ^^^^^^^^^^^^^^^^^^^^^^^
  File "/home/ec2-user/flask_miniproject1/.venv/lib64/python3.12/site-packages/flask/app.py", line 902, in dispatch_request
    return self.ensure_sync(self.view_functions[rule.endpoint])(**view_args)  # type: ignore[no-any-return]
           ^^^^^^^^^^^^^^^^^^^^^^^^^^^^^^^^^^^^^^^^^^^^^^^^^^^^^^^^^^^^^^^^^
  File "/home/ec2-user/flask_miniproject1/.venv/lib64/python3.12/site-packages/flask/views.py", line 110, in view
    return current_app.ensure_sync(self.dispatch_request)(**kwargs)  # type: ignore[no-any-return]
           ^^^^^^^^^^^^^^^^^^^^^^^^^^^^^^^^^^^^^^^^^^^^^^^^^^^^^^^^
  File "/home/ec2-user/flask_miniproject1/.venv/lib64/python3.12/site-packages/flask/views.py", line 191, in dispatch_request
    return current_app.ensure_sync(meth)(**kwargs)  # type: ignore[no-any-return]
           ^^^^^^^^^^^^^^^^^^^^^^^^^^^^^^^^^^^^^^^
  File "/home/ec2-user/flask_miniproject1/app/routes/choices.py", line 36, in get
    choices = Choices.filter_by(question_id=question_id).all()
              ^^^^^^^^^^^^^^^^^
AttributeError: type object 'Choices' has no attribute 'filter_by'
[2025-01-15 03:04:54 +0000] [10487] [INFO] Handling signal: term
[2025-01-15 03:04:54 +0000] [10489] [INFO] Worker exiting (pid: 10489)
[2025-01-15 03:04:54 +0000] [10492] [INFO] Worker exiting (pid: 10492)
[2025-01-15 03:04:54 +0000] [10493] [INFO] Worker exiting (pid: 10493)
[2025-01-15 03:04:54 +0000] [10494] [INFO] Worker exiting (pid: 10494)
[2025-01-15 03:04:54 +0000] [10487] [ERROR] Worker (pid:10489) was sent SIGTERM!
[2025-01-15 03:04:54 +0000] [10487] [ERROR] Worker (pid:10492) was sent SIGTERM!
[2025-01-15 03:04:54 +0000] [10487] [INFO] Shutting down: Master
[2025-01-15 03:04:56 +0000] [11432] [INFO] Starting gunicorn 23.0.0
[2025-01-15 03:04:56 +0000] [11432] [INFO] Listening at: http://127.0.0.1:8000 (11432)
[2025-01-15 03:04:56 +0000] [11432] [INFO] Using worker: sync
[2025-01-15 03:04:56 +0000] [11434] [INFO] Booting worker with pid: 11434
[2025-01-15 03:04:56 +0000] [11437] [INFO] Booting worker with pid: 11437
[2025-01-15 03:04:56 +0000] [11438] [INFO] Booting worker with pid: 11438
[2025-01-15 03:04:56 +0000] [11439] [INFO] Booting worker with pid: 11439
[2025-01-15 03:06:23 +0000] [11432] [INFO] Handling signal: term
[2025-01-15 03:06:23 +0000] [11434] [INFO] Worker exiting (pid: 11434)
[2025-01-15 03:06:23 +0000] [11437] [INFO] Worker exiting (pid: 11437)
[2025-01-15 03:06:23 +0000] [11438] [INFO] Worker exiting (pid: 11438)
[2025-01-15 03:06:23 +0000] [11439] [INFO] Worker exiting (pid: 11439)
[2025-01-15 03:06:23 +0000] [11432] [ERROR] Worker (pid:11434) was sent SIGTERM!
[2025-01-15 03:06:23 +0000] [11432] [ERROR] Worker (pid:11437) was sent SIGTERM!
[2025-01-15 03:06:23 +0000] [11432] [INFO] Shutting down: Master
[2025-01-15 03:06:28 +0000] [12728] [INFO] Starting gunicorn 23.0.0
[2025-01-15 03:06:28 +0000] [12728] [INFO] Listening at: http://127.0.0.1:8000 (12728)
[2025-01-15 03:06:28 +0000] [12728] [INFO] Using worker: sync
[2025-01-15 03:06:28 +0000] [12730] [INFO] Booting worker with pid: 12730
[2025-01-15 03:06:28 +0000] [12731] [INFO] Booting worker with pid: 12731
[2025-01-15 03:06:28 +0000] [12735] [INFO] Booting worker with pid: 12735
[2025-01-15 03:06:28 +0000] [12734] [INFO] Booting worker with pid: 12734
[2025-01-15 03:07:48 +0000] [12728] [INFO] Handling signal: term
[2025-01-15 03:07:48 +0000] [12730] [INFO] Worker exiting (pid: 12730)
[2025-01-15 03:07:48 +0000] [12731] [INFO] Worker exiting (pid: 12731)
[2025-01-15 03:07:48 +0000] [12734] [INFO] Worker exiting (pid: 12734)
[2025-01-15 03:07:48 +0000] [12735] [INFO] Worker exiting (pid: 12735)
[2025-01-15 03:07:49 +0000] [12728] [ERROR] Worker (pid:12730) was sent SIGTERM!
[2025-01-15 03:07:49 +0000] [12728] [ERROR] Worker (pid:12731) was sent SIGTERM!
[2025-01-15 03:07:49 +0000] [12728] [INFO] Shutting down: Master
[2025-01-15 03:08:00 +0000] [13420] [INFO] Starting gunicorn 23.0.0
[2025-01-15 03:08:00 +0000] [13420] [INFO] Listening at: http://127.0.0.1:8000 (13420)
[2025-01-15 03:08:00 +0000] [13420] [INFO] Using worker: sync
[2025-01-15 03:08:00 +0000] [13422] [INFO] Booting worker with pid: 13422
[2025-01-15 03:08:00 +0000] [13425] [INFO] Booting worker with pid: 13425
[2025-01-15 03:08:00 +0000] [13426] [INFO] Booting worker with pid: 13426
[2025-01-15 03:08:00 +0000] [13427] [INFO] Booting worker with pid: 13427
[2025-01-15 03:08:25,929] ERROR in app: Exception on /question/1 [GET]
Traceback (most recent call last):
  File "/home/ec2-user/flask_miniproject1/.venv/lib64/python3.12/site-packages/flask/app.py", line 1511, in wsgi_app
    response = self.full_dispatch_request()
               ^^^^^^^^^^^^^^^^^^^^^^^^^^^^
  File "/home/ec2-user/flask_miniproject1/.venv/lib64/python3.12/site-packages/flask/app.py", line 919, in full_dispatch_request
    rv = self.handle_user_exception(e)
         ^^^^^^^^^^^^^^^^^^^^^^^^^^^^^
  File "/home/ec2-user/flask_miniproject1/.venv/lib64/python3.12/site-packages/flask/app.py", line 917, in full_dispatch_request
    rv = self.dispatch_request()
         ^^^^^^^^^^^^^^^^^^^^^^^
  File "/home/ec2-user/flask_miniproject1/.venv/lib64/python3.12/site-packages/flask/app.py", line 902, in dispatch_request
    return self.ensure_sync(self.view_functions[rule.endpoint])(**view_args)  # type: ignore[no-any-return]
           ^^^^^^^^^^^^^^^^^^^^^^^^^^^^^^^^^^^^^^^^^^^^^^^^^^^^^^^^^^^^^^^^^
  File "/home/ec2-user/flask_miniproject1/.venv/lib64/python3.12/site-packages/flask/views.py", line 110, in view
    return current_app.ensure_sync(self.dispatch_request)(**kwargs)  # type: ignore[no-any-return]
           ^^^^^^^^^^^^^^^^^^^^^^^^^^^^^^^^^^^^^^^^^^^^^^^^^^^^^^^^
  File "/home/ec2-user/flask_miniproject1/.venv/lib64/python3.12/site-packages/flask/views.py", line 191, in dispatch_request
    return current_app.ensure_sync(meth)(**kwargs)  # type: ignore[no-any-return]
           ^^^^^^^^^^^^^^^^^^^^^^^^^^^^^^^^^^^^^^^
  File "/home/ec2-user/flask_miniproject1/app/routes/questions.py", line 53, in get
    for choice in Choices.query.filter_by(question_id=question.id).all()
                  ^^^^^^^
NameError: name 'Choices' is not defined
[2025-01-15 03:08:32,896] ERROR in app: Exception on /question/1 [GET]
Traceback (most recent call last):
  File "/home/ec2-user/flask_miniproject1/.venv/lib64/python3.12/site-packages/flask/app.py", line 1511, in wsgi_app
    response = self.full_dispatch_request()
               ^^^^^^^^^^^^^^^^^^^^^^^^^^^^
  File "/home/ec2-user/flask_miniproject1/.venv/lib64/python3.12/site-packages/flask/app.py", line 919, in full_dispatch_request
    rv = self.handle_user_exception(e)
         ^^^^^^^^^^^^^^^^^^^^^^^^^^^^^
  File "/home/ec2-user/flask_miniproject1/.venv/lib64/python3.12/site-packages/flask/app.py", line 917, in full_dispatch_request
    rv = self.dispatch_request()
         ^^^^^^^^^^^^^^^^^^^^^^^
  File "/home/ec2-user/flask_miniproject1/.venv/lib64/python3.12/site-packages/flask/app.py", line 902, in dispatch_request
    return self.ensure_sync(self.view_functions[rule.endpoint])(**view_args)  # type: ignore[no-any-return]
           ^^^^^^^^^^^^^^^^^^^^^^^^^^^^^^^^^^^^^^^^^^^^^^^^^^^^^^^^^^^^^^^^^
  File "/home/ec2-user/flask_miniproject1/.venv/lib64/python3.12/site-packages/flask/views.py", line 110, in view
    return current_app.ensure_sync(self.dispatch_request)(**kwargs)  # type: ignore[no-any-return]
           ^^^^^^^^^^^^^^^^^^^^^^^^^^^^^^^^^^^^^^^^^^^^^^^^^^^^^^^^
  File "/home/ec2-user/flask_miniproject1/.venv/lib64/python3.12/site-packages/flask/views.py", line 191, in dispatch_request
    return current_app.ensure_sync(meth)(**kwargs)  # type: ignore[no-any-return]
           ^^^^^^^^^^^^^^^^^^^^^^^^^^^^^^^^^^^^^^^
  File "/home/ec2-user/flask_miniproject1/app/routes/questions.py", line 53, in get
    for choice in Choices.query.filter_by(question_id=question.id).all()
                  ^^^^^^^
NameError: name 'Choices' is not defined
[2025-01-15 03:08:42,863] ERROR in app: Exception on /question/1 [GET]
Traceback (most recent call last):
  File "/home/ec2-user/flask_miniproject1/.venv/lib64/python3.12/site-packages/flask/app.py", line 1511, in wsgi_app
    response = self.full_dispatch_request()
               ^^^^^^^^^^^^^^^^^^^^^^^^^^^^
  File "/home/ec2-user/flask_miniproject1/.venv/lib64/python3.12/site-packages/flask/app.py", line 919, in full_dispatch_request
    rv = self.handle_user_exception(e)
         ^^^^^^^^^^^^^^^^^^^^^^^^^^^^^
  File "/home/ec2-user/flask_miniproject1/.venv/lib64/python3.12/site-packages/flask/app.py", line 917, in full_dispatch_request
    rv = self.dispatch_request()
         ^^^^^^^^^^^^^^^^^^^^^^^
  File "/home/ec2-user/flask_miniproject1/.venv/lib64/python3.12/site-packages/flask/app.py", line 902, in dispatch_request
    return self.ensure_sync(self.view_functions[rule.endpoint])(**view_args)  # type: ignore[no-any-return]
           ^^^^^^^^^^^^^^^^^^^^^^^^^^^^^^^^^^^^^^^^^^^^^^^^^^^^^^^^^^^^^^^^^
  File "/home/ec2-user/flask_miniproject1/.venv/lib64/python3.12/site-packages/flask/views.py", line 110, in view
    return current_app.ensure_sync(self.dispatch_request)(**kwargs)  # type: ignore[no-any-return]
           ^^^^^^^^^^^^^^^^^^^^^^^^^^^^^^^^^^^^^^^^^^^^^^^^^^^^^^^^
  File "/home/ec2-user/flask_miniproject1/.venv/lib64/python3.12/site-packages/flask/views.py", line 191, in dispatch_request
    return current_app.ensure_sync(meth)(**kwargs)  # type: ignore[no-any-return]
           ^^^^^^^^^^^^^^^^^^^^^^^^^^^^^^^^^^^^^^^
  File "/home/ec2-user/flask_miniproject1/app/routes/questions.py", line 53, in get
    for choice in Choices.query.filter_by(question_id=question.id).all()
                  ^^^^^^^
NameError: name 'Choices' is not defined
[2025-01-15 03:10:00 +0000] [13420] [INFO] Handling signal: term
[2025-01-15 03:10:00 +0000] [13422] [INFO] Worker exiting (pid: 13422)
[2025-01-15 03:10:00 +0000] [13425] [INFO] Worker exiting (pid: 13425)
[2025-01-15 03:10:00 +0000] [13426] [INFO] Worker exiting (pid: 13426)
[2025-01-15 03:10:00 +0000] [13427] [INFO] Worker exiting (pid: 13427)
[2025-01-15 03:10:00 +0000] [13420] [ERROR] Worker (pid:13422) was sent SIGTERM!
[2025-01-15 03:10:00 +0000] [13420] [ERROR] Worker (pid:13425) was sent SIGTERM!
[2025-01-15 03:10:00 +0000] [13420] [INFO] Shutting down: Master
[2025-01-15 03:10:02 +0000] [13963] [INFO] Starting gunicorn 23.0.0
[2025-01-15 03:10:02 +0000] [13963] [INFO] Listening at: http://127.0.0.1:8000 (13963)
[2025-01-15 03:10:02 +0000] [13963] [INFO] Using worker: sync
[2025-01-15 03:10:02 +0000] [13965] [INFO] Booting worker with pid: 13965
[2025-01-15 03:10:02 +0000] [13966] [INFO] Booting worker with pid: 13966
[2025-01-15 03:10:02 +0000] [13969] [INFO] Booting worker with pid: 13969
[2025-01-15 03:10:02 +0000] [13970] [INFO] Booting worker with pid: 13970
[2025-01-15 04:06:03 +0000] [19560] [INFO] Starting gunicorn 23.0.0
[2025-01-15 04:06:03 +0000] [19560] [ERROR] Connection in use: ('127.0.0.1', 8000)
[2025-01-15 04:06:03 +0000] [19560] [ERROR] connection to ('127.0.0.1', 8000) failed: [Errno 98] Address already in use
[2025-01-15 04:06:04 +0000] [19560] [ERROR] Connection in use: ('127.0.0.1', 8000)
[2025-01-15 04:06:04 +0000] [19560] [ERROR] connection to ('127.0.0.1', 8000) failed: [Errno 98] Address already in use
[2025-01-15 04:06:05 +0000] [19560] [ERROR] Connection in use: ('127.0.0.1', 8000)
[2025-01-15 04:06:05 +0000] [19560] [ERROR] connection to ('127.0.0.1', 8000) failed: [Errno 98] Address already in use
[2025-01-15 04:06:06 +0000] [19560] [ERROR] Connection in use: ('127.0.0.1', 8000)
[2025-01-15 04:06:06 +0000] [19560] [ERROR] connection to ('127.0.0.1', 8000) failed: [Errno 98] Address already in use
[2025-01-15 04:06:07 +0000] [19560] [ERROR] Connection in use: ('127.0.0.1', 8000)
[2025-01-15 04:06:07 +0000] [19560] [ERROR] connection to ('127.0.0.1', 8000) failed: [Errno 98] Address already in use
[2025-01-15 04:06:08 +0000] [19560] [ERROR] Can't connect to ('127.0.0.1', 8000)
[2025-01-15 04:50:34 +0000] [2587] [INFO] Starting gunicorn 23.0.0
[2025-01-15 04:50:34 +0000] [2587] [INFO] Listening at: http://127.0.0.1:8000 (2587)
[2025-01-15 04:50:34 +0000] [2587] [INFO] Using worker: sync
[2025-01-15 04:50:34 +0000] [2590] [INFO] Booting worker with pid: 2590
[2025-01-15 04:50:34 +0000] [2589] [INFO] Booting worker with pid: 2589
[2025-01-15 04:50:34 +0000] [2593] [INFO] Booting worker with pid: 2593
[2025-01-15 04:50:34 +0000] [2594] [INFO] Booting worker with pid: 2594
[2025-01-15 04:50:36 +0000] [2593] [ERROR] Exception in worker process
Traceback (most recent call last):
  File "/home/ec2-user/flask_miniproject1/.venv/lib64/python3.12/site-packages/gunicorn/arbiter.py", line 608, in spawn_worker
    worker.init_process()
  File "/home/ec2-user/flask_miniproject1/.venv/lib64/python3.12/site-packages/gunicorn/workers/base.py", line 135, in init_process
    self.load_wsgi()
  File "/home/ec2-user/flask_miniproject1/.venv/lib64/python3.12/site-packages/gunicorn/workers/base.py", line 147, in load_wsgi
    self.wsgi = self.app.wsgi()
                ^^^^^^^^^^^^^^^
  File "/home/ec2-user/flask_miniproject1/.venv/lib64/python3.12/site-packages/gunicorn/app/base.py", line 66, in wsgi
    self.callable = self.load()
                    ^^^^^^^^^^^
  File "/home/ec2-user/flask_miniproject1/.venv/lib64/python3.12/site-packages/gunicorn/app/wsgiapp.py", line 57, in load
    return self.load_wsgiapp()
           ^^^^^^^^^^^^^^^^^^^
  File "/home/ec2-user/flask_miniproject1/.venv/lib64/python3.12/site-packages/gunicorn/app/wsgiapp.py", line 47, in load_wsgiapp
    return util.import_app(self.app_uri)
           ^^^^^^^^^^^^^^^^^^^^^^^^^^^^^
  File "/home/ec2-user/flask_miniproject1/.venv/lib64/python3.12/site-packages/gunicorn/util.py", line 370, in import_app
    mod = importlib.import_module(module)
          ^^^^^^^^^^^^^^^^^^^^^^^^^^^^^^^
  File "/usr/lib64/python3.12/importlib/__init__.py", line 90, in import_module
    return _bootstrap._gcd_import(name[level:], package, level)
           ^^^^^^^^^^^^^^^^^^^^^^^^^^^^^^^^^^^^^^^^^^^^^^^^^^^^
  File "<frozen importlib._bootstrap>", line 1387, in _gcd_import
  File "<frozen importlib._bootstrap>", line 1360, in _find_and_load
  File "<frozen importlib._bootstrap>", line 1331, in _find_and_load_unlocked
  File "<frozen importlib._bootstrap>", line 935, in _load_unlocked
  File "<frozen importlib._bootstrap_external>", line 995, in exec_module
  File "<frozen importlib._bootstrap>", line 488, in _call_with_frames_removed
  File "/home/ec2-user/flask_miniproject1/wsgi.py", line 3, in <module>
    app = create_app()
          ^^^^^^^^^^^^
  File "/home/ec2-user/flask_miniproject1/app/__init__.py", line 30, in create_app
    from .routes.questions import question_blp,questions_blp
  File "/home/ec2-user/flask_miniproject1/app/routes/questions.py", line 57
    >>>>>>> 6fe3647445a980bf9c94ef49232878850e50ce94
            ^
SyntaxError: invalid decimal literal
[2025-01-15 04:50:36 +0000] [2593] [INFO] Worker exiting (pid: 2593)
[2025-01-15 04:50:36 +0000] [2594] [ERROR] Exception in worker process
Traceback (most recent call last):
  File "/home/ec2-user/flask_miniproject1/.venv/lib64/python3.12/site-packages/gunicorn/arbiter.py", line 608, in spawn_worker
    worker.init_process()
  File "/home/ec2-user/flask_miniproject1/.venv/lib64/python3.12/site-packages/gunicorn/workers/base.py", line 135, in init_process
    self.load_wsgi()
  File "/home/ec2-user/flask_miniproject1/.venv/lib64/python3.12/site-packages/gunicorn/workers/base.py", line 147, in load_wsgi
    self.wsgi = self.app.wsgi()
                ^^^^^^^^^^^^^^^
  File "/home/ec2-user/flask_miniproject1/.venv/lib64/python3.12/site-packages/gunicorn/app/base.py", line 66, in wsgi
    self.callable = self.load()
                    ^^^^^^^^^^^
  File "/home/ec2-user/flask_miniproject1/.venv/lib64/python3.12/site-packages/gunicorn/app/wsgiapp.py", line 57, in load
    return self.load_wsgiapp()
           ^^^^^^^^^^^^^^^^^^^
  File "/home/ec2-user/flask_miniproject1/.venv/lib64/python3.12/site-packages/gunicorn/app/wsgiapp.py", line 47, in load_wsgiapp
    return util.import_app(self.app_uri)
           ^^^^^^^^^^^^^^^^^^^^^^^^^^^^^
  File "/home/ec2-user/flask_miniproject1/.venv/lib64/python3.12/site-packages/gunicorn/util.py", line 370, in import_app
    mod = importlib.import_module(module)
          ^^^^^^^^^^^^^^^^^^^^^^^^^^^^^^^
  File "/usr/lib64/python3.12/importlib/__init__.py", line 90, in import_module
    return _bootstrap._gcd_import(name[level:], package, level)
           ^^^^^^^^^^^^^^^^^^^^^^^^^^^^^^^^^^^^^^^^^^^^^^^^^^^^
  File "<frozen importlib._bootstrap>", line 1387, in _gcd_import
  File "<frozen importlib._bootstrap>", line 1360, in _find_and_load
  File "<frozen importlib._bootstrap>", line 1331, in _find_and_load_unlocked
  File "<frozen importlib._bootstrap>", line 935, in _load_unlocked
  File "<frozen importlib._bootstrap_external>", line 995, in exec_module
  File "<frozen importlib._bootstrap>", line 488, in _call_with_frames_removed
  File "/home/ec2-user/flask_miniproject1/wsgi.py", line 3, in <module>
    app = create_app()
          ^^^^^^^^^^^^
  File "/home/ec2-user/flask_miniproject1/app/__init__.py", line 30, in create_app
    from .routes.questions import question_blp,questions_blp
  File "/home/ec2-user/flask_miniproject1/app/routes/questions.py", line 57
    >>>>>>> 6fe3647445a980bf9c94ef49232878850e50ce94
            ^
SyntaxError: invalid decimal literal
[2025-01-15 04:50:36 +0000] [2594] [INFO] Worker exiting (pid: 2594)
[2025-01-15 04:50:36 +0000] [2589] [ERROR] Exception in worker process
Traceback (most recent call last):
  File "/home/ec2-user/flask_miniproject1/.venv/lib64/python3.12/site-packages/gunicorn/arbiter.py", line 608, in spawn_worker
    worker.init_process()
  File "/home/ec2-user/flask_miniproject1/.venv/lib64/python3.12/site-packages/gunicorn/workers/base.py", line 135, in init_process
    self.load_wsgi()
  File "/home/ec2-user/flask_miniproject1/.venv/lib64/python3.12/site-packages/gunicorn/workers/base.py", line 147, in load_wsgi
    self.wsgi = self.app.wsgi()
                ^^^^^^^^^^^^^^^
  File "/home/ec2-user/flask_miniproject1/.venv/lib64/python3.12/site-packages/gunicorn/app/base.py", line 66, in wsgi
    self.callable = self.load()
                    ^^^^^^^^^^^
  File "/home/ec2-user/flask_miniproject1/.venv/lib64/python3.12/site-packages/gunicorn/app/wsgiapp.py", line 57, in load
    return self.load_wsgiapp()
           ^^^^^^^^^^^^^^^^^^^
  File "/home/ec2-user/flask_miniproject1/.venv/lib64/python3.12/site-packages/gunicorn/app/wsgiapp.py", line 47, in load_wsgiapp
    return util.import_app(self.app_uri)
           ^^^^^^^^^^^^^^^^^^^^^^^^^^^^^
  File "/home/ec2-user/flask_miniproject1/.venv/lib64/python3.12/site-packages/gunicorn/util.py", line 370, in import_app
    mod = importlib.import_module(module)
          ^^^^^^^^^^^^^^^^^^^^^^^^^^^^^^^
  File "/usr/lib64/python3.12/importlib/__init__.py", line 90, in import_module
    return _bootstrap._gcd_import(name[level:], package, level)
           ^^^^^^^^^^^^^^^^^^^^^^^^^^^^^^^^^^^^^^^^^^^^^^^^^^^^
  File "<frozen importlib._bootstrap>", line 1387, in _gcd_import
  File "<frozen importlib._bootstrap>", line 1360, in _find_and_load
  File "<frozen importlib._bootstrap>", line 1331, in _find_and_load_unlocked
  File "<frozen importlib._bootstrap>", line 935, in _load_unlocked
  File "<frozen importlib._bootstrap_external>", line 995, in exec_module
  File "<frozen importlib._bootstrap>", line 488, in _call_with_frames_removed
  File "/home/ec2-user/flask_miniproject1/wsgi.py", line 3, in <module>
    app = create_app()
          ^^^^^^^^^^^^
  File "/home/ec2-user/flask_miniproject1/app/__init__.py", line 30, in create_app
    from .routes.questions import question_blp,questions_blp
  File "/home/ec2-user/flask_miniproject1/app/routes/questions.py", line 57
    >>>>>>> 6fe3647445a980bf9c94ef49232878850e50ce94
            ^
SyntaxError: invalid decimal literal
[2025-01-15 04:50:36 +0000] [2589] [INFO] Worker exiting (pid: 2589)
[2025-01-15 04:50:36 +0000] [2590] [ERROR] Exception in worker process
Traceback (most recent call last):
  File "/home/ec2-user/flask_miniproject1/.venv/lib64/python3.12/site-packages/gunicorn/arbiter.py", line 608, in spawn_worker
    worker.init_process()
  File "/home/ec2-user/flask_miniproject1/.venv/lib64/python3.12/site-packages/gunicorn/workers/base.py", line 135, in init_process
    self.load_wsgi()
  File "/home/ec2-user/flask_miniproject1/.venv/lib64/python3.12/site-packages/gunicorn/workers/base.py", line 147, in load_wsgi
    self.wsgi = self.app.wsgi()
                ^^^^^^^^^^^^^^^
  File "/home/ec2-user/flask_miniproject1/.venv/lib64/python3.12/site-packages/gunicorn/app/base.py", line 66, in wsgi
    self.callable = self.load()
                    ^^^^^^^^^^^
  File "/home/ec2-user/flask_miniproject1/.venv/lib64/python3.12/site-packages/gunicorn/app/wsgiapp.py", line 57, in load
    return self.load_wsgiapp()
           ^^^^^^^^^^^^^^^^^^^
  File "/home/ec2-user/flask_miniproject1/.venv/lib64/python3.12/site-packages/gunicorn/app/wsgiapp.py", line 47, in load_wsgiapp
    return util.import_app(self.app_uri)
           ^^^^^^^^^^^^^^^^^^^^^^^^^^^^^
  File "/home/ec2-user/flask_miniproject1/.venv/lib64/python3.12/site-packages/gunicorn/util.py", line 370, in import_app
    mod = importlib.import_module(module)
          ^^^^^^^^^^^^^^^^^^^^^^^^^^^^^^^
  File "/usr/lib64/python3.12/importlib/__init__.py", line 90, in import_module
    return _bootstrap._gcd_import(name[level:], package, level)
           ^^^^^^^^^^^^^^^^^^^^^^^^^^^^^^^^^^^^^^^^^^^^^^^^^^^^
  File "<frozen importlib._bootstrap>", line 1387, in _gcd_import
  File "<frozen importlib._bootstrap>", line 1360, in _find_and_load
  File "<frozen importlib._bootstrap>", line 1331, in _find_and_load_unlocked
  File "<frozen importlib._bootstrap>", line 935, in _load_unlocked
  File "<frozen importlib._bootstrap_external>", line 995, in exec_module
  File "<frozen importlib._bootstrap>", line 488, in _call_with_frames_removed
  File "/home/ec2-user/flask_miniproject1/wsgi.py", line 3, in <module>
    app = create_app()
          ^^^^^^^^^^^^
  File "/home/ec2-user/flask_miniproject1/app/__init__.py", line 30, in create_app
    from .routes.questions import question_blp,questions_blp
  File "/home/ec2-user/flask_miniproject1/app/routes/questions.py", line 57
    >>>>>>> 6fe3647445a980bf9c94ef49232878850e50ce94
            ^
SyntaxError: invalid decimal literal
[2025-01-15 04:50:36 +0000] [2590] [INFO] Worker exiting (pid: 2590)
[2025-01-15 04:50:37 +0000] [2587] [ERROR] Worker (pid:2590) exited with code 3
[2025-01-15 04:50:37 +0000] [2587] [ERROR] Worker (pid:2589) was sent SIGTERM!
[2025-01-15 04:50:37 +0000] [2587] [ERROR] Worker (pid:2593) was sent SIGTERM!
[2025-01-15 04:50:37 +0000] [2587] [ERROR] Worker (pid:2594) was sent SIGTERM!
[2025-01-15 04:50:37 +0000] [2587] [ERROR] Shutting down: Master
[2025-01-15 04:50:37 +0000] [2587] [ERROR] Reason: Worker failed to boot.
[2025-01-15 04:55:15 +0000] [2828] [INFO] Starting gunicorn 23.0.0
[2025-01-15 04:55:15 +0000] [2828] [INFO] Listening at: http://127.0.0.1:8000 (2828)
[2025-01-15 04:55:15 +0000] [2828] [INFO] Using worker: sync
[2025-01-15 04:55:15 +0000] [2830] [INFO] Booting worker with pid: 2830
[2025-01-15 04:55:15 +0000] [2831] [INFO] Booting worker with pid: 2831
[2025-01-15 04:55:15 +0000] [2832] [INFO] Booting worker with pid: 2832
[2025-01-15 04:55:15 +0000] [2834] [INFO] Booting worker with pid: 2834
[2025-01-15 04:55:17 +0000] [2831] [ERROR] Exception in worker process
Traceback (most recent call last):
  File "/home/ec2-user/flask_miniproject1/.venv/lib64/python3.12/site-packages/gunicorn/arbiter.py", line 608, in spawn_worker
    worker.init_process()
  File "/home/ec2-user/flask_miniproject1/.venv/lib64/python3.12/site-packages/gunicorn/workers/base.py", line 135, in init_process
    self.load_wsgi()
  File "/home/ec2-user/flask_miniproject1/.venv/lib64/python3.12/site-packages/gunicorn/workers/base.py", line 147, in load_wsgi
    self.wsgi = self.app.wsgi()
                ^^^^^^^^^^^^^^^
  File "/home/ec2-user/flask_miniproject1/.venv/lib64/python3.12/site-packages/gunicorn/app/base.py", line 66, in wsgi
    self.callable = self.load()
                    ^^^^^^^^^^^
  File "/home/ec2-user/flask_miniproject1/.venv/lib64/python3.12/site-packages/gunicorn/app/wsgiapp.py", line 57, in load
    return self.load_wsgiapp()
           ^^^^^^^^^^^^^^^^^^^
  File "/home/ec2-user/flask_miniproject1/.venv/lib64/python3.12/site-packages/gunicorn/app/wsgiapp.py", line 47, in load_wsgiapp
    return util.import_app(self.app_uri)
           ^^^^^^^^^^^^^^^^^^^^^^^^^^^^^
  File "/home/ec2-user/flask_miniproject1/.venv/lib64/python3.12/site-packages/gunicorn/util.py", line 370, in import_app
    mod = importlib.import_module(module)
          ^^^^^^^^^^^^^^^^^^^^^^^^^^^^^^^
  File "/usr/lib64/python3.12/importlib/__init__.py", line 90, in import_module
    return _bootstrap._gcd_import(name[level:], package, level)
           ^^^^^^^^^^^^^^^^^^^^^^^^^^^^^^^^^^^^^^^^^^^^^^^^^^^^
  File "<frozen importlib._bootstrap>", line 1387, in _gcd_import
  File "<frozen importlib._bootstrap>", line 1360, in _find_and_load
  File "<frozen importlib._bootstrap>", line 1331, in _find_and_load_unlocked
  File "<frozen importlib._bootstrap>", line 935, in _load_unlocked
  File "<frozen importlib._bootstrap_external>", line 995, in exec_module
  File "<frozen importlib._bootstrap>", line 488, in _call_with_frames_removed
  File "/home/ec2-user/flask_miniproject1/wsgi.py", line 3, in <module>
    app = create_app()
          ^^^^^^^^^^^^
  File "/home/ec2-user/flask_miniproject1/app/__init__.py", line 30, in create_app
    from .routes.questions import question_blp,questions_blp
  File "/home/ec2-user/flask_miniproject1/app/routes/questions.py", line 57
    >>>>>>> 6fe3647445a980bf9c94ef49232878850e50ce94
            ^
SyntaxError: invalid decimal literal
[2025-01-15 04:55:17 +0000] [2831] [INFO] Worker exiting (pid: 2831)
[2025-01-15 04:55:17 +0000] [2830] [ERROR] Exception in worker process
Traceback (most recent call last):
  File "/home/ec2-user/flask_miniproject1/.venv/lib64/python3.12/site-packages/gunicorn/arbiter.py", line 608, in spawn_worker
    worker.init_process()
  File "/home/ec2-user/flask_miniproject1/.venv/lib64/python3.12/site-packages/gunicorn/workers/base.py", line 135, in init_process
    self.load_wsgi()
  File "/home/ec2-user/flask_miniproject1/.venv/lib64/python3.12/site-packages/gunicorn/workers/base.py", line 147, in load_wsgi
    self.wsgi = self.app.wsgi()
                ^^^^^^^^^^^^^^^
  File "/home/ec2-user/flask_miniproject1/.venv/lib64/python3.12/site-packages/gunicorn/app/base.py", line 66, in wsgi
    self.callable = self.load()
                    ^^^^^^^^^^^
  File "/home/ec2-user/flask_miniproject1/.venv/lib64/python3.12/site-packages/gunicorn/app/wsgiapp.py", line 57, in load
    return self.load_wsgiapp()
           ^^^^^^^^^^^^^^^^^^^
  File "/home/ec2-user/flask_miniproject1/.venv/lib64/python3.12/site-packages/gunicorn/app/wsgiapp.py", line 47, in load_wsgiapp
    return util.import_app(self.app_uri)
           ^^^^^^^^^^^^^^^^^^^^^^^^^^^^^
  File "/home/ec2-user/flask_miniproject1/.venv/lib64/python3.12/site-packages/gunicorn/util.py", line 370, in import_app
    mod = importlib.import_module(module)
          ^^^^^^^^^^^^^^^^^^^^^^^^^^^^^^^
  File "/usr/lib64/python3.12/importlib/__init__.py", line 90, in import_module
    return _bootstrap._gcd_import(name[level:], package, level)
           ^^^^^^^^^^^^^^^^^^^^^^^^^^^^^^^^^^^^^^^^^^^^^^^^^^^^
  File "<frozen importlib._bootstrap>", line 1387, in _gcd_import
  File "<frozen importlib._bootstrap>", line 1360, in _find_and_load
  File "<frozen importlib._bootstrap>", line 1331, in _find_and_load_unlocked
  File "<frozen importlib._bootstrap>", line 935, in _load_unlocked
  File "<frozen importlib._bootstrap_external>", line 995, in exec_module
  File "<frozen importlib._bootstrap>", line 488, in _call_with_frames_removed
  File "/home/ec2-user/flask_miniproject1/wsgi.py", line 3, in <module>
    app = create_app()
          ^^^^^^^^^^^^
  File "/home/ec2-user/flask_miniproject1/app/__init__.py", line 30, in create_app
    from .routes.questions import question_blp,questions_blp
  File "/home/ec2-user/flask_miniproject1/app/routes/questions.py", line 57
    >>>>>>> 6fe3647445a980bf9c94ef49232878850e50ce94
            ^
SyntaxError: invalid decimal literal
[2025-01-15 04:55:17 +0000] [2830] [INFO] Worker exiting (pid: 2830)
[2025-01-15 04:55:17 +0000] [2834] [ERROR] Exception in worker process
Traceback (most recent call last):
  File "/home/ec2-user/flask_miniproject1/.venv/lib64/python3.12/site-packages/gunicorn/arbiter.py", line 608, in spawn_worker
    worker.init_process()
  File "/home/ec2-user/flask_miniproject1/.venv/lib64/python3.12/site-packages/gunicorn/workers/base.py", line 135, in init_process
    self.load_wsgi()
  File "/home/ec2-user/flask_miniproject1/.venv/lib64/python3.12/site-packages/gunicorn/workers/base.py", line 147, in load_wsgi
    self.wsgi = self.app.wsgi()
                ^^^^^^^^^^^^^^^
  File "/home/ec2-user/flask_miniproject1/.venv/lib64/python3.12/site-packages/gunicorn/app/base.py", line 66, in wsgi
    self.callable = self.load()
                    ^^^^^^^^^^^
  File "/home/ec2-user/flask_miniproject1/.venv/lib64/python3.12/site-packages/gunicorn/app/wsgiapp.py", line 57, in load
    return self.load_wsgiapp()
           ^^^^^^^^^^^^^^^^^^^
  File "/home/ec2-user/flask_miniproject1/.venv/lib64/python3.12/site-packages/gunicorn/app/wsgiapp.py", line 47, in load_wsgiapp
    return util.import_app(self.app_uri)
           ^^^^^^^^^^^^^^^^^^^^^^^^^^^^^
  File "/home/ec2-user/flask_miniproject1/.venv/lib64/python3.12/site-packages/gunicorn/util.py", line 370, in import_app
    mod = importlib.import_module(module)
          ^^^^^^^^^^^^^^^^^^^^^^^^^^^^^^^
  File "/usr/lib64/python3.12/importlib/__init__.py", line 90, in import_module
    return _bootstrap._gcd_import(name[level:], package, level)
           ^^^^^^^^^^^^^^^^^^^^^^^^^^^^^^^^^^^^^^^^^^^^^^^^^^^^
  File "<frozen importlib._bootstrap>", line 1387, in _gcd_import
  File "<frozen importlib._bootstrap>", line 1360, in _find_and_load
  File "<frozen importlib._bootstrap>", line 1331, in _find_and_load_unlocked
  File "<frozen importlib._bootstrap>", line 935, in _load_unlocked
  File "<frozen importlib._bootstrap_external>", line 995, in exec_module
  File "<frozen importlib._bootstrap>", line 488, in _call_with_frames_removed
  File "/home/ec2-user/flask_miniproject1/wsgi.py", line 3, in <module>
    app = create_app()
          ^^^^^^^^^^^^
  File "/home/ec2-user/flask_miniproject1/app/__init__.py", line 30, in create_app
    from .routes.questions import question_blp,questions_blp
  File "/home/ec2-user/flask_miniproject1/app/routes/questions.py", line 57
    >>>>>>> 6fe3647445a980bf9c94ef49232878850e50ce94
            ^
SyntaxError: invalid decimal literal
[2025-01-15 04:55:17 +0000] [2834] [INFO] Worker exiting (pid: 2834)
[2025-01-15 04:55:17 +0000] [2832] [ERROR] Exception in worker process
Traceback (most recent call last):
  File "/home/ec2-user/flask_miniproject1/.venv/lib64/python3.12/site-packages/gunicorn/arbiter.py", line 608, in spawn_worker
    worker.init_process()
  File "/home/ec2-user/flask_miniproject1/.venv/lib64/python3.12/site-packages/gunicorn/workers/base.py", line 135, in init_process
    self.load_wsgi()
  File "/home/ec2-user/flask_miniproject1/.venv/lib64/python3.12/site-packages/gunicorn/workers/base.py", line 147, in load_wsgi
    self.wsgi = self.app.wsgi()
                ^^^^^^^^^^^^^^^
  File "/home/ec2-user/flask_miniproject1/.venv/lib64/python3.12/site-packages/gunicorn/app/base.py", line 66, in wsgi
    self.callable = self.load()
                    ^^^^^^^^^^^
  File "/home/ec2-user/flask_miniproject1/.venv/lib64/python3.12/site-packages/gunicorn/app/wsgiapp.py", line 57, in load
    return self.load_wsgiapp()
           ^^^^^^^^^^^^^^^^^^^
  File "/home/ec2-user/flask_miniproject1/.venv/lib64/python3.12/site-packages/gunicorn/app/wsgiapp.py", line 47, in load_wsgiapp
    return util.import_app(self.app_uri)
           ^^^^^^^^^^^^^^^^^^^^^^^^^^^^^
  File "/home/ec2-user/flask_miniproject1/.venv/lib64/python3.12/site-packages/gunicorn/util.py", line 370, in import_app
    mod = importlib.import_module(module)
          ^^^^^^^^^^^^^^^^^^^^^^^^^^^^^^^
  File "/usr/lib64/python3.12/importlib/__init__.py", line 90, in import_module
    return _bootstrap._gcd_import(name[level:], package, level)
           ^^^^^^^^^^^^^^^^^^^^^^^^^^^^^^^^^^^^^^^^^^^^^^^^^^^^
  File "<frozen importlib._bootstrap>", line 1387, in _gcd_import
  File "<frozen importlib._bootstrap>", line 1360, in _find_and_load
  File "<frozen importlib._bootstrap>", line 1331, in _find_and_load_unlocked
  File "<frozen importlib._bootstrap>", line 935, in _load_unlocked
  File "<frozen importlib._bootstrap_external>", line 995, in exec_module
  File "<frozen importlib._bootstrap>", line 488, in _call_with_frames_removed
  File "/home/ec2-user/flask_miniproject1/wsgi.py", line 3, in <module>
    app = create_app()
          ^^^^^^^^^^^^
  File "/home/ec2-user/flask_miniproject1/app/__init__.py", line 30, in create_app
    from .routes.questions import question_blp,questions_blp
  File "/home/ec2-user/flask_miniproject1/app/routes/questions.py", line 57
    >>>>>>> 6fe3647445a980bf9c94ef49232878850e50ce94
            ^
SyntaxError: invalid decimal literal
[2025-01-15 04:55:17 +0000] [2832] [INFO] Worker exiting (pid: 2832)
[2025-01-15 04:55:17 +0000] [2828] [ERROR] Worker (pid:2830) exited with code 3
[2025-01-15 04:55:17 +0000] [2828] [ERROR] Worker (pid:2832) was sent SIGTERM!
[2025-01-15 04:55:17 +0000] [2828] [ERROR] Worker (pid:2834) was sent SIGTERM!
[2025-01-15 04:55:17 +0000] [2828] [ERROR] Worker (pid:2831) was sent SIGTERM!
[2025-01-15 04:55:17 +0000] [2828] [ERROR] Shutting down: Master
[2025-01-15 04:55:17 +0000] [2828] [ERROR] Reason: Worker failed to boot.
[2025-01-15 04:59:22 +0000] [3082] [INFO] Starting gunicorn 23.0.0
[2025-01-15 04:59:22 +0000] [3082] [INFO] Listening at: http://127.0.0.1:8000 (3082)
[2025-01-15 04:59:22 +0000] [3082] [INFO] Using worker: sync
[2025-01-15 04:59:22 +0000] [3084] [INFO] Booting worker with pid: 3084
[2025-01-15 04:59:22 +0000] [3085] [INFO] Booting worker with pid: 3085
[2025-01-15 04:59:22 +0000] [3088] [INFO] Booting worker with pid: 3088
[2025-01-15 04:59:22 +0000] [3089] [INFO] Booting worker with pid: 3089
[2025-01-15 04:59:24 +0000] [3084] [ERROR] Exception in worker process
Traceback (most recent call last):
  File "/home/ec2-user/flask_miniproject1/.venv/lib64/python3.12/site-packages/gunicorn/arbiter.py", line 608, in spawn_worker
    worker.init_process()
  File "/home/ec2-user/flask_miniproject1/.venv/lib64/python3.12/site-packages/gunicorn/workers/base.py", line 135, in init_process
    self.load_wsgi()
  File "/home/ec2-user/flask_miniproject1/.venv/lib64/python3.12/site-packages/gunicorn/workers/base.py", line 147, in load_wsgi
    self.wsgi = self.app.wsgi()
                ^^^^^^^^^^^^^^^
  File "/home/ec2-user/flask_miniproject1/.venv/lib64/python3.12/site-packages/gunicorn/app/base.py", line 66, in wsgi
    self.callable = self.load()
                    ^^^^^^^^^^^
  File "/home/ec2-user/flask_miniproject1/.venv/lib64/python3.12/site-packages/gunicorn/app/wsgiapp.py", line 57, in load
    return self.load_wsgiapp()
           ^^^^^^^^^^^^^^^^^^^
  File "/home/ec2-user/flask_miniproject1/.venv/lib64/python3.12/site-packages/gunicorn/app/wsgiapp.py", line 47, in load_wsgiapp
    return util.import_app(self.app_uri)
           ^^^^^^^^^^^^^^^^^^^^^^^^^^^^^
  File "/home/ec2-user/flask_miniproject1/.venv/lib64/python3.12/site-packages/gunicorn/util.py", line 370, in import_app
    mod = importlib.import_module(module)
          ^^^^^^^^^^^^^^^^^^^^^^^^^^^^^^^
  File "/usr/lib64/python3.12/importlib/__init__.py", line 90, in import_module
    return _bootstrap._gcd_import(name[level:], package, level)
           ^^^^^^^^^^^^^^^^^^^^^^^^^^^^^^^^^^^^^^^^^^^^^^^^^^^^
  File "<frozen importlib._bootstrap>", line 1387, in _gcd_import
  File "<frozen importlib._bootstrap>", line 1360, in _find_and_load
  File "<frozen importlib._bootstrap>", line 1331, in _find_and_load_unlocked
  File "<frozen importlib._bootstrap>", line 935, in _load_unlocked
  File "<frozen importlib._bootstrap_external>", line 995, in exec_module
  File "<frozen importlib._bootstrap>", line 488, in _call_with_frames_removed
  File "/home/ec2-user/flask_miniproject1/wsgi.py", line 3, in <module>
    app = create_app()
          ^^^^^^^^^^^^
  File "/home/ec2-user/flask_miniproject1/app/__init__.py", line 32, in create_app
    from .routes.choices import choices_blp
  File "/home/ec2-user/flask_miniproject1/app/routes/choices.py", line 40
    >>>>>>> 6fe3647445a980bf9c94ef49232878850e50ce94
            ^
SyntaxError: invalid decimal literal
[2025-01-15 04:59:24 +0000] [3084] [INFO] Worker exiting (pid: 3084)
[2025-01-15 04:59:24 +0000] [3085] [ERROR] Exception in worker process
Traceback (most recent call last):
  File "/home/ec2-user/flask_miniproject1/.venv/lib64/python3.12/site-packages/gunicorn/arbiter.py", line 608, in spawn_worker
    worker.init_process()
  File "/home/ec2-user/flask_miniproject1/.venv/lib64/python3.12/site-packages/gunicorn/workers/base.py", line 135, in init_process
    self.load_wsgi()
  File "/home/ec2-user/flask_miniproject1/.venv/lib64/python3.12/site-packages/gunicorn/workers/base.py", line 147, in load_wsgi
    self.wsgi = self.app.wsgi()
                ^^^^^^^^^^^^^^^
  File "/home/ec2-user/flask_miniproject1/.venv/lib64/python3.12/site-packages/gunicorn/app/base.py", line 66, in wsgi
    self.callable = self.load()
                    ^^^^^^^^^^^
  File "/home/ec2-user/flask_miniproject1/.venv/lib64/python3.12/site-packages/gunicorn/app/wsgiapp.py", line 57, in load
    return self.load_wsgiapp()
           ^^^^^^^^^^^^^^^^^^^
  File "/home/ec2-user/flask_miniproject1/.venv/lib64/python3.12/site-packages/gunicorn/app/wsgiapp.py", line 47, in load_wsgiapp
    return util.import_app(self.app_uri)
           ^^^^^^^^^^^^^^^^^^^^^^^^^^^^^
  File "/home/ec2-user/flask_miniproject1/.venv/lib64/python3.12/site-packages/gunicorn/util.py", line 370, in import_app
    mod = importlib.import_module(module)
          ^^^^^^^^^^^^^^^^^^^^^^^^^^^^^^^
  File "/usr/lib64/python3.12/importlib/__init__.py", line 90, in import_module
    return _bootstrap._gcd_import(name[level:], package, level)
           ^^^^^^^^^^^^^^^^^^^^^^^^^^^^^^^^^^^^^^^^^^^^^^^^^^^^
  File "<frozen importlib._bootstrap>", line 1387, in _gcd_import
  File "<frozen importlib._bootstrap>", line 1360, in _find_and_load
  File "<frozen importlib._bootstrap>", line 1331, in _find_and_load_unlocked
  File "<frozen importlib._bootstrap>", line 935, in _load_unlocked
  File "<frozen importlib._bootstrap_external>", line 995, in exec_module
  File "<frozen importlib._bootstrap>", line 488, in _call_with_frames_removed
  File "/home/ec2-user/flask_miniproject1/wsgi.py", line 3, in <module>
    app = create_app()
          ^^^^^^^^^^^^
  File "/home/ec2-user/flask_miniproject1/app/__init__.py", line 32, in create_app
    from .routes.choices import choices_blp
  File "/home/ec2-user/flask_miniproject1/app/routes/choices.py", line 40
    >>>>>>> 6fe3647445a980bf9c94ef49232878850e50ce94
            ^
SyntaxError: invalid decimal literal
[2025-01-15 04:59:24 +0000] [3085] [INFO] Worker exiting (pid: 3085)
[2025-01-15 04:59:24 +0000] [3088] [ERROR] Exception in worker process
Traceback (most recent call last):
  File "/home/ec2-user/flask_miniproject1/.venv/lib64/python3.12/site-packages/gunicorn/arbiter.py", line 608, in spawn_worker
    worker.init_process()
  File "/home/ec2-user/flask_miniproject1/.venv/lib64/python3.12/site-packages/gunicorn/workers/base.py", line 135, in init_process
    self.load_wsgi()
  File "/home/ec2-user/flask_miniproject1/.venv/lib64/python3.12/site-packages/gunicorn/workers/base.py", line 147, in load_wsgi
    self.wsgi = self.app.wsgi()
                ^^^^^^^^^^^^^^^
  File "/home/ec2-user/flask_miniproject1/.venv/lib64/python3.12/site-packages/gunicorn/app/base.py", line 66, in wsgi
    self.callable = self.load()
                    ^^^^^^^^^^^
  File "/home/ec2-user/flask_miniproject1/.venv/lib64/python3.12/site-packages/gunicorn/app/wsgiapp.py", line 57, in load
    return self.load_wsgiapp()
           ^^^^^^^^^^^^^^^^^^^
  File "/home/ec2-user/flask_miniproject1/.venv/lib64/python3.12/site-packages/gunicorn/app/wsgiapp.py", line 47, in load_wsgiapp
    return util.import_app(self.app_uri)
           ^^^^^^^^^^^^^^^^^^^^^^^^^^^^^
  File "/home/ec2-user/flask_miniproject1/.venv/lib64/python3.12/site-packages/gunicorn/util.py", line 370, in import_app
    mod = importlib.import_module(module)
          ^^^^^^^^^^^^^^^^^^^^^^^^^^^^^^^
  File "/usr/lib64/python3.12/importlib/__init__.py", line 90, in import_module
    return _bootstrap._gcd_import(name[level:], package, level)
           ^^^^^^^^^^^^^^^^^^^^^^^^^^^^^^^^^^^^^^^^^^^^^^^^^^^^
  File "<frozen importlib._bootstrap>", line 1387, in _gcd_import
  File "<frozen importlib._bootstrap>", line 1360, in _find_and_load
  File "<frozen importlib._bootstrap>", line 1331, in _find_and_load_unlocked
  File "<frozen importlib._bootstrap>", line 935, in _load_unlocked
  File "<frozen importlib._bootstrap_external>", line 995, in exec_module
  File "<frozen importlib._bootstrap>", line 488, in _call_with_frames_removed
  File "/home/ec2-user/flask_miniproject1/wsgi.py", line 3, in <module>
    app = create_app()
          ^^^^^^^^^^^^
  File "/home/ec2-user/flask_miniproject1/app/__init__.py", line 32, in create_app
    from .routes.choices import choices_blp
  File "/home/ec2-user/flask_miniproject1/app/routes/choices.py", line 40
    >>>>>>> 6fe3647445a980bf9c94ef49232878850e50ce94
            ^
SyntaxError: invalid decimal literal
[2025-01-15 04:59:24 +0000] [3088] [INFO] Worker exiting (pid: 3088)
[2025-01-15 04:59:24 +0000] [3089] [ERROR] Exception in worker process
Traceback (most recent call last):
  File "/home/ec2-user/flask_miniproject1/.venv/lib64/python3.12/site-packages/gunicorn/arbiter.py", line 608, in spawn_worker
    worker.init_process()
  File "/home/ec2-user/flask_miniproject1/.venv/lib64/python3.12/site-packages/gunicorn/workers/base.py", line 135, in init_process
    self.load_wsgi()
  File "/home/ec2-user/flask_miniproject1/.venv/lib64/python3.12/site-packages/gunicorn/workers/base.py", line 147, in load_wsgi
    self.wsgi = self.app.wsgi()
                ^^^^^^^^^^^^^^^
  File "/home/ec2-user/flask_miniproject1/.venv/lib64/python3.12/site-packages/gunicorn/app/base.py", line 66, in wsgi
    self.callable = self.load()
                    ^^^^^^^^^^^
  File "/home/ec2-user/flask_miniproject1/.venv/lib64/python3.12/site-packages/gunicorn/app/wsgiapp.py", line 57, in load
    return self.load_wsgiapp()
           ^^^^^^^^^^^^^^^^^^^
  File "/home/ec2-user/flask_miniproject1/.venv/lib64/python3.12/site-packages/gunicorn/app/wsgiapp.py", line 47, in load_wsgiapp
    return util.import_app(self.app_uri)
           ^^^^^^^^^^^^^^^^^^^^^^^^^^^^^
  File "/home/ec2-user/flask_miniproject1/.venv/lib64/python3.12/site-packages/gunicorn/util.py", line 370, in import_app
    mod = importlib.import_module(module)
          ^^^^^^^^^^^^^^^^^^^^^^^^^^^^^^^
  File "/usr/lib64/python3.12/importlib/__init__.py", line 90, in import_module
    return _bootstrap._gcd_import(name[level:], package, level)
           ^^^^^^^^^^^^^^^^^^^^^^^^^^^^^^^^^^^^^^^^^^^^^^^^^^^^
  File "<frozen importlib._bootstrap>", line 1387, in _gcd_import
  File "<frozen importlib._bootstrap>", line 1360, in _find_and_load
  File "<frozen importlib._bootstrap>", line 1331, in _find_and_load_unlocked
  File "<frozen importlib._bootstrap>", line 935, in _load_unlocked
  File "<frozen importlib._bootstrap_external>", line 995, in exec_module
  File "<frozen importlib._bootstrap>", line 488, in _call_with_frames_removed
  File "/home/ec2-user/flask_miniproject1/wsgi.py", line 3, in <module>
    app = create_app()
          ^^^^^^^^^^^^
  File "/home/ec2-user/flask_miniproject1/app/__init__.py", line 32, in create_app
    from .routes.choices import choices_blp
  File "/home/ec2-user/flask_miniproject1/app/routes/choices.py", line 40
    >>>>>>> 6fe3647445a980bf9c94ef49232878850e50ce94
            ^
SyntaxError: invalid decimal literal
[2025-01-15 04:59:24 +0000] [3089] [INFO] Worker exiting (pid: 3089)
[2025-01-15 04:59:24 +0000] [3082] [ERROR] Worker (pid:3084) exited with code 3
[2025-01-15 04:59:24 +0000] [3082] [ERROR] Worker (pid:3085) was sent SIGTERM!
[2025-01-15 04:59:24 +0000] [3082] [ERROR] Worker (pid:3089) was sent SIGTERM!
[2025-01-15 04:59:24 +0000] [3082] [ERROR] Worker (pid:3088) was sent SIGTERM!
[2025-01-15 04:59:25 +0000] [3082] [ERROR] Shutting down: Master
[2025-01-15 04:59:25 +0000] [3082] [ERROR] Reason: Worker failed to boot.
[2025-01-15 05:01:57 +0000] [3245] [INFO] Starting gunicorn 23.0.0
[2025-01-15 05:01:57 +0000] [3245] [INFO] Listening at: http://127.0.0.1:8000 (3245)
[2025-01-15 05:01:57 +0000] [3245] [INFO] Using worker: sync
[2025-01-15 05:01:57 +0000] [3247] [INFO] Booting worker with pid: 3247
[2025-01-15 05:01:58 +0000] [3250] [INFO] Booting worker with pid: 3250
[2025-01-15 05:01:58 +0000] [3251] [INFO] Booting worker with pid: 3251
[2025-01-15 05:01:58 +0000] [3252] [INFO] Booting worker with pid: 3252
[2025-01-15 05:02:27,377] ERROR in app: Exception on /choice/1 [GET]
Traceback (most recent call last):
  File "/home/ec2-user/flask_miniproject1/.venv/lib64/python3.12/site-packages/flask/app.py", line 1511, in wsgi_app
    response = self.full_dispatch_request()
               ^^^^^^^^^^^^^^^^^^^^^^^^^^^^
  File "/home/ec2-user/flask_miniproject1/.venv/lib64/python3.12/site-packages/flask/app.py", line 919, in full_dispatch_request
    rv = self.handle_user_exception(e)
         ^^^^^^^^^^^^^^^^^^^^^^^^^^^^^
  File "/home/ec2-user/flask_miniproject1/.venv/lib64/python3.12/site-packages/flask/app.py", line 917, in full_dispatch_request
    rv = self.dispatch_request()
         ^^^^^^^^^^^^^^^^^^^^^^^
  File "/home/ec2-user/flask_miniproject1/.venv/lib64/python3.12/site-packages/flask/app.py", line 902, in dispatch_request
    return self.ensure_sync(self.view_functions[rule.endpoint])(**view_args)  # type: ignore[no-any-return]
           ^^^^^^^^^^^^^^^^^^^^^^^^^^^^^^^^^^^^^^^^^^^^^^^^^^^^^^^^^^^^^^^^^
  File "/home/ec2-user/flask_miniproject1/.venv/lib64/python3.12/site-packages/flask/views.py", line 110, in view
    return current_app.ensure_sync(self.dispatch_request)(**kwargs)  # type: ignore[no-any-return]
           ^^^^^^^^^^^^^^^^^^^^^^^^^^^^^^^^^^^^^^^^^^^^^^^^^^^^^^^^
  File "/home/ec2-user/flask_miniproject1/.venv/lib64/python3.12/site-packages/flask/views.py", line 191, in dispatch_request
    return current_app.ensure_sync(meth)(**kwargs)  # type: ignore[no-any-return]
           ^^^^^^^^^^^^^^^^^^^^^^^^^^^^^^^^^^^^^^^
  File "/home/ec2-user/flask_miniproject1/app/routes/choices.py", line 39, in get
    return {"choices":[{"id":choice.id,"content":choice.content,"is_active":choice.is_active,"sqe":choice.sqe}for choice in choices]}
                                                                                                                            ^^^^^^^
TypeError: 'Choices' object is not iterable
[2025-01-15 05:06:43,692] ERROR in app: Exception on /choice/1 [GET]
Traceback (most recent call last):
  File "/home/ec2-user/flask_miniproject1/.venv/lib64/python3.12/site-packages/flask/app.py", line 1511, in wsgi_app
    response = self.full_dispatch_request()
               ^^^^^^^^^^^^^^^^^^^^^^^^^^^^
  File "/home/ec2-user/flask_miniproject1/.venv/lib64/python3.12/site-packages/flask/app.py", line 919, in full_dispatch_request
    rv = self.handle_user_exception(e)
         ^^^^^^^^^^^^^^^^^^^^^^^^^^^^^
  File "/home/ec2-user/flask_miniproject1/.venv/lib64/python3.12/site-packages/flask/app.py", line 917, in full_dispatch_request
    rv = self.dispatch_request()
         ^^^^^^^^^^^^^^^^^^^^^^^
  File "/home/ec2-user/flask_miniproject1/.venv/lib64/python3.12/site-packages/flask/app.py", line 902, in dispatch_request
    return self.ensure_sync(self.view_functions[rule.endpoint])(**view_args)  # type: ignore[no-any-return]
           ^^^^^^^^^^^^^^^^^^^^^^^^^^^^^^^^^^^^^^^^^^^^^^^^^^^^^^^^^^^^^^^^^
  File "/home/ec2-user/flask_miniproject1/.venv/lib64/python3.12/site-packages/flask/views.py", line 110, in view
    return current_app.ensure_sync(self.dispatch_request)(**kwargs)  # type: ignore[no-any-return]
           ^^^^^^^^^^^^^^^^^^^^^^^^^^^^^^^^^^^^^^^^^^^^^^^^^^^^^^^^
  File "/home/ec2-user/flask_miniproject1/.venv/lib64/python3.12/site-packages/flask/views.py", line 191, in dispatch_request
    return current_app.ensure_sync(meth)(**kwargs)  # type: ignore[no-any-return]
           ^^^^^^^^^^^^^^^^^^^^^^^^^^^^^^^^^^^^^^^
  File "/home/ec2-user/flask_miniproject1/app/routes/choices.py", line 39, in get
    return {"choices":[{"id":choice.id,"content":choice.content,"is_active":choice.is_active,"sqe":choice.sqe}for choice in choices]}
                                                                                                                            ^^^^^^^
TypeError: 'Choices' object is not iterable
[2025-01-15 05:14:37,818] ERROR in app: Exception on /choice/1 [GET]
Traceback (most recent call last):
  File "/home/ec2-user/flask_miniproject1/.venv/lib64/python3.12/site-packages/flask/app.py", line 1511, in wsgi_app
    response = self.full_dispatch_request()
               ^^^^^^^^^^^^^^^^^^^^^^^^^^^^
  File "/home/ec2-user/flask_miniproject1/.venv/lib64/python3.12/site-packages/flask/app.py", line 919, in full_dispatch_request
    rv = self.handle_user_exception(e)
         ^^^^^^^^^^^^^^^^^^^^^^^^^^^^^
  File "/home/ec2-user/flask_miniproject1/.venv/lib64/python3.12/site-packages/flask/app.py", line 917, in full_dispatch_request
    rv = self.dispatch_request()
         ^^^^^^^^^^^^^^^^^^^^^^^
  File "/home/ec2-user/flask_miniproject1/.venv/lib64/python3.12/site-packages/flask/app.py", line 902, in dispatch_request
    return self.ensure_sync(self.view_functions[rule.endpoint])(**view_args)  # type: ignore[no-any-return]
           ^^^^^^^^^^^^^^^^^^^^^^^^^^^^^^^^^^^^^^^^^^^^^^^^^^^^^^^^^^^^^^^^^
  File "/home/ec2-user/flask_miniproject1/.venv/lib64/python3.12/site-packages/flask/views.py", line 110, in view
    return current_app.ensure_sync(self.dispatch_request)(**kwargs)  # type: ignore[no-any-return]
           ^^^^^^^^^^^^^^^^^^^^^^^^^^^^^^^^^^^^^^^^^^^^^^^^^^^^^^^^
  File "/home/ec2-user/flask_miniproject1/.venv/lib64/python3.12/site-packages/flask/views.py", line 191, in dispatch_request
    return current_app.ensure_sync(meth)(**kwargs)  # type: ignore[no-any-return]
           ^^^^^^^^^^^^^^^^^^^^^^^^^^^^^^^^^^^^^^^
  File "/home/ec2-user/flask_miniproject1/app/routes/choices.py", line 39, in get
    return {"choices":[{"id":choice.id,"content":choice.content,"is_active":choice.is_active,"sqe":choice.sqe}for choice in choices]}
                                                                                                                            ^^^^^^^
TypeError: 'Choices' object is not iterable
[2025-01-15 05:14:39,068] ERROR in app: Exception on /choice/1 [GET]
Traceback (most recent call last):
  File "/home/ec2-user/flask_miniproject1/.venv/lib64/python3.12/site-packages/flask/app.py", line 1511, in wsgi_app
    response = self.full_dispatch_request()
               ^^^^^^^^^^^^^^^^^^^^^^^^^^^^
  File "/home/ec2-user/flask_miniproject1/.venv/lib64/python3.12/site-packages/flask/app.py", line 919, in full_dispatch_request
    rv = self.handle_user_exception(e)
         ^^^^^^^^^^^^^^^^^^^^^^^^^^^^^
  File "/home/ec2-user/flask_miniproject1/.venv/lib64/python3.12/site-packages/flask/app.py", line 917, in full_dispatch_request
    rv = self.dispatch_request()
         ^^^^^^^^^^^^^^^^^^^^^^^
  File "/home/ec2-user/flask_miniproject1/.venv/lib64/python3.12/site-packages/flask/app.py", line 902, in dispatch_request
    return self.ensure_sync(self.view_functions[rule.endpoint])(**view_args)  # type: ignore[no-any-return]
           ^^^^^^^^^^^^^^^^^^^^^^^^^^^^^^^^^^^^^^^^^^^^^^^^^^^^^^^^^^^^^^^^^
  File "/home/ec2-user/flask_miniproject1/.venv/lib64/python3.12/site-packages/flask/views.py", line 110, in view
    return current_app.ensure_sync(self.dispatch_request)(**kwargs)  # type: ignore[no-any-return]
           ^^^^^^^^^^^^^^^^^^^^^^^^^^^^^^^^^^^^^^^^^^^^^^^^^^^^^^^^
  File "/home/ec2-user/flask_miniproject1/.venv/lib64/python3.12/site-packages/flask/views.py", line 191, in dispatch_request
    return current_app.ensure_sync(meth)(**kwargs)  # type: ignore[no-any-return]
           ^^^^^^^^^^^^^^^^^^^^^^^^^^^^^^^^^^^^^^^
  File "/home/ec2-user/flask_miniproject1/app/routes/choices.py", line 39, in get
    return {"choices":[{"id":choice.id,"content":choice.content,"is_active":choice.is_active,"sqe":choice.sqe}for choice in choices]}
                                                                                                                            ^^^^^^^
TypeError: 'Choices' object is not iterable
[2025-01-15 05:14:39,729] ERROR in app: Exception on /choice/1 [GET]
Traceback (most recent call last):
  File "/home/ec2-user/flask_miniproject1/.venv/lib64/python3.12/site-packages/flask/app.py", line 1511, in wsgi_app
    response = self.full_dispatch_request()
               ^^^^^^^^^^^^^^^^^^^^^^^^^^^^
  File "/home/ec2-user/flask_miniproject1/.venv/lib64/python3.12/site-packages/flask/app.py", line 919, in full_dispatch_request
    rv = self.handle_user_exception(e)
         ^^^^^^^^^^^^^^^^^^^^^^^^^^^^^
  File "/home/ec2-user/flask_miniproject1/.venv/lib64/python3.12/site-packages/flask/app.py", line 917, in full_dispatch_request
    rv = self.dispatch_request()
         ^^^^^^^^^^^^^^^^^^^^^^^
  File "/home/ec2-user/flask_miniproject1/.venv/lib64/python3.12/site-packages/flask/app.py", line 902, in dispatch_request
    return self.ensure_sync(self.view_functions[rule.endpoint])(**view_args)  # type: ignore[no-any-return]
           ^^^^^^^^^^^^^^^^^^^^^^^^^^^^^^^^^^^^^^^^^^^^^^^^^^^^^^^^^^^^^^^^^
  File "/home/ec2-user/flask_miniproject1/.venv/lib64/python3.12/site-packages/flask/views.py", line 110, in view
    return current_app.ensure_sync(self.dispatch_request)(**kwargs)  # type: ignore[no-any-return]
           ^^^^^^^^^^^^^^^^^^^^^^^^^^^^^^^^^^^^^^^^^^^^^^^^^^^^^^^^
  File "/home/ec2-user/flask_miniproject1/.venv/lib64/python3.12/site-packages/flask/views.py", line 191, in dispatch_request
    return current_app.ensure_sync(meth)(**kwargs)  # type: ignore[no-any-return]
           ^^^^^^^^^^^^^^^^^^^^^^^^^^^^^^^^^^^^^^^
  File "/home/ec2-user/flask_miniproject1/app/routes/choices.py", line 39, in get
    return {"choices":[{"id":choice.id,"content":choice.content,"is_active":choice.is_active,"sqe":choice.sqe}for choice in choices]}
                                                                                                                            ^^^^^^^
TypeError: 'Choices' object is not iterable
[2025-01-15 05:20:29,261] ERROR in app: Exception on /choice/1 [GET]
Traceback (most recent call last):
  File "/home/ec2-user/flask_miniproject1/.venv/lib64/python3.12/site-packages/flask/app.py", line 1511, in wsgi_app
    response = self.full_dispatch_request()
               ^^^^^^^^^^^^^^^^^^^^^^^^^^^^
  File "/home/ec2-user/flask_miniproject1/.venv/lib64/python3.12/site-packages/flask/app.py", line 919, in full_dispatch_request
    rv = self.handle_user_exception(e)
         ^^^^^^^^^^^^^^^^^^^^^^^^^^^^^
  File "/home/ec2-user/flask_miniproject1/.venv/lib64/python3.12/site-packages/flask/app.py", line 917, in full_dispatch_request
    rv = self.dispatch_request()
         ^^^^^^^^^^^^^^^^^^^^^^^
  File "/home/ec2-user/flask_miniproject1/.venv/lib64/python3.12/site-packages/flask/app.py", line 902, in dispatch_request
    return self.ensure_sync(self.view_functions[rule.endpoint])(**view_args)  # type: ignore[no-any-return]
           ^^^^^^^^^^^^^^^^^^^^^^^^^^^^^^^^^^^^^^^^^^^^^^^^^^^^^^^^^^^^^^^^^
  File "/home/ec2-user/flask_miniproject1/.venv/lib64/python3.12/site-packages/flask/views.py", line 110, in view
    return current_app.ensure_sync(self.dispatch_request)(**kwargs)  # type: ignore[no-any-return]
           ^^^^^^^^^^^^^^^^^^^^^^^^^^^^^^^^^^^^^^^^^^^^^^^^^^^^^^^^
  File "/home/ec2-user/flask_miniproject1/.venv/lib64/python3.12/site-packages/flask/views.py", line 191, in dispatch_request
    return current_app.ensure_sync(meth)(**kwargs)  # type: ignore[no-any-return]
           ^^^^^^^^^^^^^^^^^^^^^^^^^^^^^^^^^^^^^^^
  File "/home/ec2-user/flask_miniproject1/app/routes/choices.py", line 39, in get
    return {"choices":[{"id":choice.id,"content":choice.content,"is_active":choice.is_active,"sqe":choice.sqe} for choice in choices]}
                                                                                                                            ^^^^^^^
TypeError: 'Choices' object is not iterable
[2025-01-15 05:25:00,810] ERROR in app: Exception on /choice/1 [GET]
Traceback (most recent call last):
  File "/home/ec2-user/flask_miniproject1/.venv/lib64/python3.12/site-packages/flask/app.py", line 1511, in wsgi_app
    response = self.full_dispatch_request()
               ^^^^^^^^^^^^^^^^^^^^^^^^^^^^
  File "/home/ec2-user/flask_miniproject1/.venv/lib64/python3.12/site-packages/flask/app.py", line 919, in full_dispatch_request
    rv = self.handle_user_exception(e)
         ^^^^^^^^^^^^^^^^^^^^^^^^^^^^^
  File "/home/ec2-user/flask_miniproject1/.venv/lib64/python3.12/site-packages/flask/app.py", line 917, in full_dispatch_request
    rv = self.dispatch_request()
         ^^^^^^^^^^^^^^^^^^^^^^^
  File "/home/ec2-user/flask_miniproject1/.venv/lib64/python3.12/site-packages/flask/app.py", line 902, in dispatch_request
    return self.ensure_sync(self.view_functions[rule.endpoint])(**view_args)  # type: ignore[no-any-return]
           ^^^^^^^^^^^^^^^^^^^^^^^^^^^^^^^^^^^^^^^^^^^^^^^^^^^^^^^^^^^^^^^^^
  File "/home/ec2-user/flask_miniproject1/.venv/lib64/python3.12/site-packages/flask/views.py", line 110, in view
    return current_app.ensure_sync(self.dispatch_request)(**kwargs)  # type: ignore[no-any-return]
           ^^^^^^^^^^^^^^^^^^^^^^^^^^^^^^^^^^^^^^^^^^^^^^^^^^^^^^^^
  File "/home/ec2-user/flask_miniproject1/.venv/lib64/python3.12/site-packages/flask/views.py", line 191, in dispatch_request
    return current_app.ensure_sync(meth)(**kwargs)  # type: ignore[no-any-return]
           ^^^^^^^^^^^^^^^^^^^^^^^^^^^^^^^^^^^^^^^
  File "/home/ec2-user/flask_miniproject1/app/routes/choices.py", line 39, in get
    return {"choices":[{"id":choice.id,"content":choice.content,"is_active":choice.is_active,"sqe":choice.sqe} for choice in choices]}
                                                                                                                            ^^^^^^^
TypeError: 'Choices' object is not iterable
[2025-01-15 05:27:29 +0000] [3245] [INFO] Handling signal: term
[2025-01-15 05:27:29 +0000] [3247] [INFO] Worker exiting (pid: 3247)
[2025-01-15 05:27:29 +0000] [3250] [INFO] Worker exiting (pid: 3250)
[2025-01-15 05:27:29 +0000] [3251] [INFO] Worker exiting (pid: 3251)
[2025-01-15 05:27:29 +0000] [3252] [INFO] Worker exiting (pid: 3252)
[2025-01-15 05:27:29 +0000] [3245] [ERROR] Worker (pid:3247) was sent SIGTERM!
[2025-01-15 05:27:29 +0000] [3245] [ERROR] Worker (pid:3250) was sent SIGTERM!
[2025-01-15 05:27:29 +0000] [3245] [ERROR] Worker (pid:3251) was sent SIGTERM!
[2025-01-15 05:27:29 +0000] [3245] [ERROR] Worker (pid:3252) was sent SIGTERM!
[2025-01-15 05:27:29 +0000] [3245] [INFO] Shutting down: Master
[2025-01-15 05:27:32 +0000] [4360] [INFO] Starting gunicorn 23.0.0
[2025-01-15 05:27:32 +0000] [4360] [INFO] Listening at: http://127.0.0.1:8000 (4360)
[2025-01-15 05:27:32 +0000] [4360] [INFO] Using worker: sync
[2025-01-15 05:27:32 +0000] [4362] [INFO] Booting worker with pid: 4362
[2025-01-15 05:27:32 +0000] [4365] [INFO] Booting worker with pid: 4365
[2025-01-15 05:27:32 +0000] [4366] [INFO] Booting worker with pid: 4366
[2025-01-15 05:27:32 +0000] [4367] [INFO] Booting worker with pid: 4367
[2025-01-15 05:28:10,501] ERROR in app: Exception on /question/1 [GET]
Traceback (most recent call last):
  File "/home/ec2-user/flask_miniproject1/.venv/lib64/python3.12/site-packages/flask/app.py", line 1511, in wsgi_app
    response = self.full_dispatch_request()
               ^^^^^^^^^^^^^^^^^^^^^^^^^^^^
  File "/home/ec2-user/flask_miniproject1/.venv/lib64/python3.12/site-packages/flask/app.py", line 919, in full_dispatch_request
    rv = self.handle_user_exception(e)
         ^^^^^^^^^^^^^^^^^^^^^^^^^^^^^
  File "/home/ec2-user/flask_miniproject1/.venv/lib64/python3.12/site-packages/flask/app.py", line 917, in full_dispatch_request
    rv = self.dispatch_request()
         ^^^^^^^^^^^^^^^^^^^^^^^
  File "/home/ec2-user/flask_miniproject1/.venv/lib64/python3.12/site-packages/flask/app.py", line 902, in dispatch_request
    return self.ensure_sync(self.view_functions[rule.endpoint])(**view_args)  # type: ignore[no-any-return]
           ^^^^^^^^^^^^^^^^^^^^^^^^^^^^^^^^^^^^^^^^^^^^^^^^^^^^^^^^^^^^^^^^^
  File "/home/ec2-user/flask_miniproject1/.venv/lib64/python3.12/site-packages/flask/views.py", line 110, in view
    return current_app.ensure_sync(self.dispatch_request)(**kwargs)  # type: ignore[no-any-return]
           ^^^^^^^^^^^^^^^^^^^^^^^^^^^^^^^^^^^^^^^^^^^^^^^^^^^^^^^^
  File "/home/ec2-user/flask_miniproject1/.venv/lib64/python3.12/site-packages/flask/views.py", line 191, in dispatch_request
    return current_app.ensure_sync(meth)(**kwargs)  # type: ignore[no-any-return]
           ^^^^^^^^^^^^^^^^^^^^^^^^^^^^^^^^^^^^^^^
  File "/home/ec2-user/flask_miniproject1/app/routes/questions.py", line 53, in get
    for choice in Choices.query.filter_by(question_id=question.id).all()
                  ^^^^^^^
NameError: name 'Choices' is not defined
[2025-01-15 05:28:38,443] ERROR in app: Exception on /question/1 [GET]
Traceback (most recent call last):
  File "/home/ec2-user/flask_miniproject1/.venv/lib64/python3.12/site-packages/flask/app.py", line 1511, in wsgi_app
    response = self.full_dispatch_request()
               ^^^^^^^^^^^^^^^^^^^^^^^^^^^^
  File "/home/ec2-user/flask_miniproject1/.venv/lib64/python3.12/site-packages/flask/app.py", line 919, in full_dispatch_request
    rv = self.handle_user_exception(e)
         ^^^^^^^^^^^^^^^^^^^^^^^^^^^^^
  File "/home/ec2-user/flask_miniproject1/.venv/lib64/python3.12/site-packages/flask/app.py", line 917, in full_dispatch_request
    rv = self.dispatch_request()
         ^^^^^^^^^^^^^^^^^^^^^^^
  File "/home/ec2-user/flask_miniproject1/.venv/lib64/python3.12/site-packages/flask/app.py", line 902, in dispatch_request
    return self.ensure_sync(self.view_functions[rule.endpoint])(**view_args)  # type: ignore[no-any-return]
           ^^^^^^^^^^^^^^^^^^^^^^^^^^^^^^^^^^^^^^^^^^^^^^^^^^^^^^^^^^^^^^^^^
  File "/home/ec2-user/flask_miniproject1/.venv/lib64/python3.12/site-packages/flask/views.py", line 110, in view
    return current_app.ensure_sync(self.dispatch_request)(**kwargs)  # type: ignore[no-any-return]
           ^^^^^^^^^^^^^^^^^^^^^^^^^^^^^^^^^^^^^^^^^^^^^^^^^^^^^^^^
  File "/home/ec2-user/flask_miniproject1/.venv/lib64/python3.12/site-packages/flask/views.py", line 191, in dispatch_request
    return current_app.ensure_sync(meth)(**kwargs)  # type: ignore[no-any-return]
           ^^^^^^^^^^^^^^^^^^^^^^^^^^^^^^^^^^^^^^^
  File "/home/ec2-user/flask_miniproject1/app/routes/questions.py", line 53, in get
    for choice in Choices.query.filter_by(question_id=question.id).all()
                  ^^^^^^^
NameError: name 'Choices' is not defined
[2025-01-15 05:28:47 +0000] [4360] [INFO] Handling signal: term
[2025-01-15 05:28:47 +0000] [4362] [INFO] Worker exiting (pid: 4362)
[2025-01-15 05:28:47 +0000] [4365] [INFO] Worker exiting (pid: 4365)
[2025-01-15 05:28:47 +0000] [4366] [INFO] Worker exiting (pid: 4366)
[2025-01-15 05:28:47 +0000] [4367] [INFO] Worker exiting (pid: 4367)
[2025-01-15 05:28:48 +0000] [4360] [ERROR] Worker (pid:4362) was sent SIGTERM!
[2025-01-15 05:28:48 +0000] [4360] [ERROR] Worker (pid:4365) was sent SIGTERM!
[2025-01-15 05:28:48 +0000] [4360] [ERROR] Worker (pid:4366) was sent SIGTERM!
[2025-01-15 05:28:48 +0000] [4360] [INFO] Shutting down: Master
[2025-01-15 05:32:56 +0000] [4614] [INFO] Starting gunicorn 23.0.0
[2025-01-15 05:32:56 +0000] [4614] [INFO] Listening at: http://127.0.0.1:8000 (4614)
[2025-01-15 05:32:56 +0000] [4614] [INFO] Using worker: sync
[2025-01-15 05:32:56 +0000] [4616] [INFO] Booting worker with pid: 4616
[2025-01-15 05:32:56 +0000] [4619] [INFO] Booting worker with pid: 4619
[2025-01-15 05:32:56 +0000] [4620] [INFO] Booting worker with pid: 4620
[2025-01-15 05:32:56 +0000] [4621] [INFO] Booting worker with pid: 4621
[2025-01-15 05:34:32 +0000] [4614] [INFO] Handling signal: term
[2025-01-15 05:34:32 +0000] [4616] [INFO] Worker exiting (pid: 4616)
[2025-01-15 05:34:32 +0000] [4619] [INFO] Worker exiting (pid: 4619)
[2025-01-15 05:34:32 +0000] [4620] [INFO] Worker exiting (pid: 4620)
[2025-01-15 05:34:32 +0000] [4621] [INFO] Worker exiting (pid: 4621)
[2025-01-15 05:34:32 +0000] [4614] [ERROR] Worker (pid:4616) was sent SIGTERM!
[2025-01-15 05:34:32 +0000] [4614] [ERROR] Worker (pid:4619) was sent SIGTERM!
[2025-01-15 05:34:32 +0000] [4614] [ERROR] Worker (pid:4620) was sent SIGTERM!
[2025-01-15 05:34:32 +0000] [4614] [INFO] Shutting down: Master
[2025-01-15 05:35:46 +0000] [4800] [INFO] Starting gunicorn 23.0.0
[2025-01-15 05:35:46 +0000] [4800] [INFO] Listening at: http://127.0.0.1:8000 (4800)
[2025-01-15 05:35:46 +0000] [4800] [INFO] Using worker: sync
[2025-01-15 05:35:46 +0000] [4802] [INFO] Booting worker with pid: 4802
[2025-01-15 05:35:46 +0000] [4805] [INFO] Booting worker with pid: 4805
[2025-01-15 05:35:46 +0000] [4806] [INFO] Booting worker with pid: 4806
[2025-01-15 05:35:47 +0000] [4807] [INFO] Booting worker with pid: 4807
[2025-01-15 05:52:59 +0000] [5396] [INFO] Starting gunicorn 23.0.0
[2025-01-15 05:52:59 +0000] [5396] [ERROR] Connection in use: ('127.0.0.1', 8000)
[2025-01-15 05:52:59 +0000] [5396] [ERROR] connection to ('127.0.0.1', 8000) failed: [Errno 98] Address already in use
[2025-01-15 05:53:00 +0000] [5396] [ERROR] Connection in use: ('127.0.0.1', 8000)
[2025-01-15 05:53:00 +0000] [5396] [ERROR] connection to ('127.0.0.1', 8000) failed: [Errno 98] Address already in use
[2025-01-15 05:53:01 +0000] [5396] [ERROR] Connection in use: ('127.0.0.1', 8000)
[2025-01-15 05:53:01 +0000] [5396] [ERROR] connection to ('127.0.0.1', 8000) failed: [Errno 98] Address already in use
[2025-01-15 05:53:02 +0000] [5396] [ERROR] Connection in use: ('127.0.0.1', 8000)
[2025-01-15 05:53:02 +0000] [5396] [ERROR] connection to ('127.0.0.1', 8000) failed: [Errno 98] Address already in use
[2025-01-15 05:53:03 +0000] [5396] [ERROR] Connection in use: ('127.0.0.1', 8000)
[2025-01-15 05:53:03 +0000] [5396] [ERROR] connection to ('127.0.0.1', 8000) failed: [Errno 98] Address already in use
[2025-01-15 05:53:04 +0000] [5396] [ERROR] Can't connect to ('127.0.0.1', 8000)
[2025-01-15 05:53:52 +0000] [4800] [INFO] Handling signal: term
[2025-01-15 05:53:52 +0000] [4802] [INFO] Worker exiting (pid: 4802)
[2025-01-15 05:53:52 +0000] [4805] [INFO] Worker exiting (pid: 4805)
[2025-01-15 05:53:52 +0000] [4806] [INFO] Worker exiting (pid: 4806)
[2025-01-15 05:53:52 +0000] [4807] [INFO] Worker exiting (pid: 4807)
[2025-01-15 05:53:52 +0000] [4800] [ERROR] Worker (pid:4802) was sent SIGTERM!
[2025-01-15 05:53:52 +0000] [4800] [ERROR] Worker (pid:4805) was sent SIGTERM!
[2025-01-15 05:53:52 +0000] [4800] [ERROR] Worker (pid:4806) was sent SIGTERM!
[2025-01-15 05:53:53 +0000] [4800] [INFO] Shutting down: Master
[2025-01-15 05:54:58 +0000] [5578] [INFO] Starting gunicorn 23.0.0
[2025-01-15 05:54:58 +0000] [5578] [INFO] Listening at: http://127.0.0.1:8000 (5578)
[2025-01-15 05:54:58 +0000] [5578] [INFO] Using worker: sync
[2025-01-15 05:54:58 +0000] [5580] [INFO] Booting worker with pid: 5580
[2025-01-15 05:54:58 +0000] [5583] [INFO] Booting worker with pid: 5583
[2025-01-15 05:54:58 +0000] [5584] [INFO] Booting worker with pid: 5584
[2025-01-15 05:54:58 +0000] [5585] [INFO] Booting worker with pid: 5585
[2025-01-15 06:00:42 +0000] [5578] [INFO] Handling signal: term
[2025-01-15 06:00:42 +0000] [5580] [INFO] Worker exiting (pid: 5580)
[2025-01-15 06:00:42 +0000] [5583] [INFO] Worker exiting (pid: 5583)
[2025-01-15 06:00:42 +0000] [5584] [INFO] Worker exiting (pid: 5584)
[2025-01-15 06:00:42 +0000] [5585] [INFO] Worker exiting (pid: 5585)
[2025-01-15 06:00:42 +0000] [5578] [ERROR] Worker (pid:5580) was sent SIGTERM!
[2025-01-15 06:00:42 +0000] [5578] [ERROR] Worker (pid:5583) was sent SIGTERM!
[2025-01-15 06:00:43 +0000] [5578] [ERROR] Worker (pid:5584) was sent SIGTERM!
[2025-01-15 06:00:43 +0000] [5578] [INFO] Shutting down: Master
[2025-01-15 06:00:45 +0000] [5828] [INFO] Starting gunicorn 23.0.0
[2025-01-15 06:00:45 +0000] [5828] [INFO] Listening at: http://127.0.0.1:8000 (5828)
[2025-01-15 06:00:45 +0000] [5828] [INFO] Using worker: sync
[2025-01-15 06:00:45 +0000] [5830] [INFO] Booting worker with pid: 5830
[2025-01-15 06:00:45 +0000] [5831] [INFO] Booting worker with pid: 5831
[2025-01-15 06:00:45 +0000] [5834] [INFO] Booting worker with pid: 5834
[2025-01-15 06:00:45 +0000] [5835] [INFO] Booting worker with pid: 5835
[2025-01-15 06:00:47 +0000] [5830] [ERROR] Exception in worker process
Traceback (most recent call last):
  File "/home/ec2-user/flask_miniproject1/.venv/lib64/python3.12/site-packages/gunicorn/arbiter.py", line 608, in spawn_worker
    worker.init_process()
  File "/home/ec2-user/flask_miniproject1/.venv/lib64/python3.12/site-packages/gunicorn/workers/base.py", line 135, in init_process
    self.load_wsgi()
  File "/home/ec2-user/flask_miniproject1/.venv/lib64/python3.12/site-packages/gunicorn/workers/base.py", line 147, in load_wsgi
    self.wsgi = self.app.wsgi()
                ^^^^^^^^^^^^^^^
  File "/home/ec2-user/flask_miniproject1/.venv/lib64/python3.12/site-packages/gunicorn/app/base.py", line 66, in wsgi
    self.callable = self.load()
                    ^^^^^^^^^^^
  File "/home/ec2-user/flask_miniproject1/.venv/lib64/python3.12/site-packages/gunicorn/app/wsgiapp.py", line 57, in load
    return self.load_wsgiapp()
           ^^^^^^^^^^^^^^^^^^^
  File "/home/ec2-user/flask_miniproject1/.venv/lib64/python3.12/site-packages/gunicorn/app/wsgiapp.py", line 47, in load_wsgiapp
    return util.import_app(self.app_uri)
           ^^^^^^^^^^^^^^^^^^^^^^^^^^^^^
  File "/home/ec2-user/flask_miniproject1/.venv/lib64/python3.12/site-packages/gunicorn/util.py", line 370, in import_app
    mod = importlib.import_module(module)
          ^^^^^^^^^^^^^^^^^^^^^^^^^^^^^^^
  File "/usr/lib64/python3.12/importlib/__init__.py", line 90, in import_module
    return _bootstrap._gcd_import(name[level:], package, level)
           ^^^^^^^^^^^^^^^^^^^^^^^^^^^^^^^^^^^^^^^^^^^^^^^^^^^^
  File "<frozen importlib._bootstrap>", line 1387, in _gcd_import
  File "<frozen importlib._bootstrap>", line 1360, in _find_and_load
  File "<frozen importlib._bootstrap>", line 1331, in _find_and_load_unlocked
  File "<frozen importlib._bootstrap>", line 935, in _load_unlocked
  File "<frozen importlib._bootstrap_external>", line 995, in exec_module
  File "<frozen importlib._bootstrap>", line 488, in _call_with_frames_removed
  File "/home/ec2-user/flask_miniproject1/wsgi.py", line 3, in <module>
    app = create_app()
          ^^^^^^^^^^^^
  File "/home/ec2-user/flask_miniproject1/app/__init__.py", line 34, in create_app
    from .routes.answers import answer_blp
  File "/home/ec2-user/flask_miniproject1/app/routes/answers.py", line 6, in <module>
    answer_blp = Blueprint('Answer', 'answer', url_prefix='/submit',strict_slashes=False)
                 ^^^^^^^^^^^^^^^^^^^^^^^^^^^^^^^^^^^^^^^^^^^^^^^^^^^^^^^^^^^^^^^^^^^^^^^^
  File "/home/ec2-user/flask_miniproject1/.venv/lib64/python3.12/site-packages/flask_smorest/blueprint.py", line 74, in __init__
    super().__init__(*args, **kwargs)
TypeError: Blueprint.__init__() got an unexpected keyword argument 'strict_slashes'
[2025-01-15 06:00:47 +0000] [5830] [INFO] Worker exiting (pid: 5830)
[2025-01-15 06:00:47 +0000] [5831] [ERROR] Exception in worker process
Traceback (most recent call last):
  File "/home/ec2-user/flask_miniproject1/.venv/lib64/python3.12/site-packages/gunicorn/arbiter.py", line 608, in spawn_worker
    worker.init_process()
  File "/home/ec2-user/flask_miniproject1/.venv/lib64/python3.12/site-packages/gunicorn/workers/base.py", line 135, in init_process
    self.load_wsgi()
  File "/home/ec2-user/flask_miniproject1/.venv/lib64/python3.12/site-packages/gunicorn/workers/base.py", line 147, in load_wsgi
    self.wsgi = self.app.wsgi()
                ^^^^^^^^^^^^^^^
  File "/home/ec2-user/flask_miniproject1/.venv/lib64/python3.12/site-packages/gunicorn/app/base.py", line 66, in wsgi
    self.callable = self.load()
                    ^^^^^^^^^^^
  File "/home/ec2-user/flask_miniproject1/.venv/lib64/python3.12/site-packages/gunicorn/app/wsgiapp.py", line 57, in load
    return self.load_wsgiapp()
           ^^^^^^^^^^^^^^^^^^^
  File "/home/ec2-user/flask_miniproject1/.venv/lib64/python3.12/site-packages/gunicorn/app/wsgiapp.py", line 47, in load_wsgiapp
    return util.import_app(self.app_uri)
           ^^^^^^^^^^^^^^^^^^^^^^^^^^^^^
  File "/home/ec2-user/flask_miniproject1/.venv/lib64/python3.12/site-packages/gunicorn/util.py", line 370, in import_app
    mod = importlib.import_module(module)
          ^^^^^^^^^^^^^^^^^^^^^^^^^^^^^^^
  File "/usr/lib64/python3.12/importlib/__init__.py", line 90, in import_module
    return _bootstrap._gcd_import(name[level:], package, level)
           ^^^^^^^^^^^^^^^^^^^^^^^^^^^^^^^^^^^^^^^^^^^^^^^^^^^^
  File "<frozen importlib._bootstrap>", line 1387, in _gcd_import
  File "<frozen importlib._bootstrap>", line 1360, in _find_and_load
  File "<frozen importlib._bootstrap>", line 1331, in _find_and_load_unlocked
  File "<frozen importlib._bootstrap>", line 935, in _load_unlocked
  File "<frozen importlib._bootstrap_external>", line 995, in exec_module
  File "<frozen importlib._bootstrap>", line 488, in _call_with_frames_removed
  File "/home/ec2-user/flask_miniproject1/wsgi.py", line 3, in <module>
    app = create_app()
          ^^^^^^^^^^^^
  File "/home/ec2-user/flask_miniproject1/app/__init__.py", line 34, in create_app
    from .routes.answers import answer_blp
  File "/home/ec2-user/flask_miniproject1/app/routes/answers.py", line 6, in <module>
    answer_blp = Blueprint('Answer', 'answer', url_prefix='/submit',strict_slashes=False)
                 ^^^^^^^^^^^^^^^^^^^^^^^^^^^^^^^^^^^^^^^^^^^^^^^^^^^^^^^^^^^^^^^^^^^^^^^^
  File "/home/ec2-user/flask_miniproject1/.venv/lib64/python3.12/site-packages/flask_smorest/blueprint.py", line 74, in __init__
    super().__init__(*args, **kwargs)
TypeError: Blueprint.__init__() got an unexpected keyword argument 'strict_slashes'
[2025-01-15 06:00:47 +0000] [5831] [INFO] Worker exiting (pid: 5831)
[2025-01-15 06:00:47 +0000] [5835] [ERROR] Exception in worker process
Traceback (most recent call last):
  File "/home/ec2-user/flask_miniproject1/.venv/lib64/python3.12/site-packages/gunicorn/arbiter.py", line 608, in spawn_worker
    worker.init_process()
  File "/home/ec2-user/flask_miniproject1/.venv/lib64/python3.12/site-packages/gunicorn/workers/base.py", line 135, in init_process
    self.load_wsgi()
  File "/home/ec2-user/flask_miniproject1/.venv/lib64/python3.12/site-packages/gunicorn/workers/base.py", line 147, in load_wsgi
    self.wsgi = self.app.wsgi()
                ^^^^^^^^^^^^^^^
  File "/home/ec2-user/flask_miniproject1/.venv/lib64/python3.12/site-packages/gunicorn/app/base.py", line 66, in wsgi
    self.callable = self.load()
                    ^^^^^^^^^^^
  File "/home/ec2-user/flask_miniproject1/.venv/lib64/python3.12/site-packages/gunicorn/app/wsgiapp.py", line 57, in load
    return self.load_wsgiapp()
           ^^^^^^^^^^^^^^^^^^^
  File "/home/ec2-user/flask_miniproject1/.venv/lib64/python3.12/site-packages/gunicorn/app/wsgiapp.py", line 47, in load_wsgiapp
    return util.import_app(self.app_uri)
           ^^^^^^^^^^^^^^^^^^^^^^^^^^^^^
  File "/home/ec2-user/flask_miniproject1/.venv/lib64/python3.12/site-packages/gunicorn/util.py", line 370, in import_app
    mod = importlib.import_module(module)
          ^^^^^^^^^^^^^^^^^^^^^^^^^^^^^^^
  File "/usr/lib64/python3.12/importlib/__init__.py", line 90, in import_module
    return _bootstrap._gcd_import(name[level:], package, level)
           ^^^^^^^^^^^^^^^^^^^^^^^^^^^^^^^^^^^^^^^^^^^^^^^^^^^^
  File "<frozen importlib._bootstrap>", line 1387, in _gcd_import
  File "<frozen importlib._bootstrap>", line 1360, in _find_and_load
  File "<frozen importlib._bootstrap>", line 1331, in _find_and_load_unlocked
  File "<frozen importlib._bootstrap>", line 935, in _load_unlocked
  File "<frozen importlib._bootstrap_external>", line 995, in exec_module
  File "<frozen importlib._bootstrap>", line 488, in _call_with_frames_removed
  File "/home/ec2-user/flask_miniproject1/wsgi.py", line 3, in <module>
    app = create_app()
          ^^^^^^^^^^^^
  File "/home/ec2-user/flask_miniproject1/app/__init__.py", line 34, in create_app
    from .routes.answers import answer_blp
  File "/home/ec2-user/flask_miniproject1/app/routes/answers.py", line 6, in <module>
    answer_blp = Blueprint('Answer', 'answer', url_prefix='/submit',strict_slashes=False)
                 ^^^^^^^^^^^^^^^^^^^^^^^^^^^^^^^^^^^^^^^^^^^^^^^^^^^^^^^^^^^^^^^^^^^^^^^^
  File "/home/ec2-user/flask_miniproject1/.venv/lib64/python3.12/site-packages/flask_smorest/blueprint.py", line 74, in __init__
    super().__init__(*args, **kwargs)
TypeError: Blueprint.__init__() got an unexpected keyword argument 'strict_slashes'
[2025-01-15 06:00:47 +0000] [5835] [INFO] Worker exiting (pid: 5835)
[2025-01-15 06:00:47 +0000] [5834] [ERROR] Exception in worker process
Traceback (most recent call last):
  File "/home/ec2-user/flask_miniproject1/.venv/lib64/python3.12/site-packages/gunicorn/arbiter.py", line 608, in spawn_worker
    worker.init_process()
  File "/home/ec2-user/flask_miniproject1/.venv/lib64/python3.12/site-packages/gunicorn/workers/base.py", line 135, in init_process
    self.load_wsgi()
  File "/home/ec2-user/flask_miniproject1/.venv/lib64/python3.12/site-packages/gunicorn/workers/base.py", line 147, in load_wsgi
    self.wsgi = self.app.wsgi()
                ^^^^^^^^^^^^^^^
  File "/home/ec2-user/flask_miniproject1/.venv/lib64/python3.12/site-packages/gunicorn/app/base.py", line 66, in wsgi
    self.callable = self.load()
                    ^^^^^^^^^^^
  File "/home/ec2-user/flask_miniproject1/.venv/lib64/python3.12/site-packages/gunicorn/app/wsgiapp.py", line 57, in load
    return self.load_wsgiapp()
           ^^^^^^^^^^^^^^^^^^^
  File "/home/ec2-user/flask_miniproject1/.venv/lib64/python3.12/site-packages/gunicorn/app/wsgiapp.py", line 47, in load_wsgiapp
    return util.import_app(self.app_uri)
           ^^^^^^^^^^^^^^^^^^^^^^^^^^^^^
  File "/home/ec2-user/flask_miniproject1/.venv/lib64/python3.12/site-packages/gunicorn/util.py", line 370, in import_app
    mod = importlib.import_module(module)
          ^^^^^^^^^^^^^^^^^^^^^^^^^^^^^^^
  File "/usr/lib64/python3.12/importlib/__init__.py", line 90, in import_module
    return _bootstrap._gcd_import(name[level:], package, level)
           ^^^^^^^^^^^^^^^^^^^^^^^^^^^^^^^^^^^^^^^^^^^^^^^^^^^^
  File "<frozen importlib._bootstrap>", line 1387, in _gcd_import
  File "<frozen importlib._bootstrap>", line 1360, in _find_and_load
  File "<frozen importlib._bootstrap>", line 1331, in _find_and_load_unlocked
  File "<frozen importlib._bootstrap>", line 935, in _load_unlocked
  File "<frozen importlib._bootstrap_external>", line 995, in exec_module
  File "<frozen importlib._bootstrap>", line 488, in _call_with_frames_removed
  File "/home/ec2-user/flask_miniproject1/wsgi.py", line 3, in <module>
    app = create_app()
          ^^^^^^^^^^^^
  File "/home/ec2-user/flask_miniproject1/app/__init__.py", line 34, in create_app
    from .routes.answers import answer_blp
  File "/home/ec2-user/flask_miniproject1/app/routes/answers.py", line 6, in <module>
    answer_blp = Blueprint('Answer', 'answer', url_prefix='/submit',strict_slashes=False)
                 ^^^^^^^^^^^^^^^^^^^^^^^^^^^^^^^^^^^^^^^^^^^^^^^^^^^^^^^^^^^^^^^^^^^^^^^^
  File "/home/ec2-user/flask_miniproject1/.venv/lib64/python3.12/site-packages/flask_smorest/blueprint.py", line 74, in __init__
    super().__init__(*args, **kwargs)
TypeError: Blueprint.__init__() got an unexpected keyword argument 'strict_slashes'
[2025-01-15 06:00:47 +0000] [5834] [INFO] Worker exiting (pid: 5834)
[2025-01-15 06:00:47 +0000] [5828] [ERROR] Worker (pid:5830) exited with code 3
[2025-01-15 06:00:47 +0000] [5828] [ERROR] Worker (pid:5831) was sent SIGTERM!
[2025-01-15 06:00:47 +0000] [5828] [ERROR] Worker (pid:5835) was sent SIGTERM!
[2025-01-15 06:00:47 +0000] [5828] [ERROR] Worker (pid:5834) was sent SIGTERM!
[2025-01-15 06:00:47 +0000] [5828] [ERROR] Shutting down: Master
[2025-01-15 06:00:47 +0000] [5828] [ERROR] Reason: Worker failed to boot.
[2025-01-15 06:01:12 +0000] [5857] [INFO] Starting gunicorn 23.0.0
[2025-01-15 06:01:12 +0000] [5857] [INFO] Listening at: http://127.0.0.1:8000 (5857)
[2025-01-15 06:01:12 +0000] [5857] [INFO] Using worker: sync
[2025-01-15 06:01:12 +0000] [5858] [INFO] Booting worker with pid: 5858
[2025-01-15 06:01:12 +0000] [5859] [INFO] Booting worker with pid: 5859
[2025-01-15 06:01:12 +0000] [5861] [INFO] Booting worker with pid: 5861
[2025-01-15 06:01:12 +0000] [5863] [INFO] Booting worker with pid: 5863
[2025-01-15 06:01:14 +0000] [5858] [ERROR] Exception in worker process
Traceback (most recent call last):
  File "/home/ec2-user/flask_miniproject1/.venv/lib64/python3.12/site-packages/gunicorn/arbiter.py", line 608, in spawn_worker
    worker.init_process()
  File "/home/ec2-user/flask_miniproject1/.venv/lib64/python3.12/site-packages/gunicorn/workers/base.py", line 135, in init_process
    self.load_wsgi()
  File "/home/ec2-user/flask_miniproject1/.venv/lib64/python3.12/site-packages/gunicorn/workers/base.py", line 147, in load_wsgi
    self.wsgi = self.app.wsgi()
                ^^^^^^^^^^^^^^^
  File "/home/ec2-user/flask_miniproject1/.venv/lib64/python3.12/site-packages/gunicorn/app/base.py", line 66, in wsgi
    self.callable = self.load()
                    ^^^^^^^^^^^
  File "/home/ec2-user/flask_miniproject1/.venv/lib64/python3.12/site-packages/gunicorn/app/wsgiapp.py", line 57, in load
    return self.load_wsgiapp()
           ^^^^^^^^^^^^^^^^^^^
  File "/home/ec2-user/flask_miniproject1/.venv/lib64/python3.12/site-packages/gunicorn/app/wsgiapp.py", line 47, in load_wsgiapp
    return util.import_app(self.app_uri)
           ^^^^^^^^^^^^^^^^^^^^^^^^^^^^^
  File "/home/ec2-user/flask_miniproject1/.venv/lib64/python3.12/site-packages/gunicorn/util.py", line 370, in import_app
    mod = importlib.import_module(module)
          ^^^^^^^^^^^^^^^^^^^^^^^^^^^^^^^
  File "/usr/lib64/python3.12/importlib/__init__.py", line 90, in import_module
    return _bootstrap._gcd_import(name[level:], package, level)
           ^^^^^^^^^^^^^^^^^^^^^^^^^^^^^^^^^^^^^^^^^^^^^^^^^^^^
  File "<frozen importlib._bootstrap>", line 1387, in _gcd_import
  File "<frozen importlib._bootstrap>", line 1360, in _find_and_load
  File "<frozen importlib._bootstrap>", line 1331, in _find_and_load_unlocked
  File "<frozen importlib._bootstrap>", line 935, in _load_unlocked
  File "<frozen importlib._bootstrap_external>", line 995, in exec_module
  File "<frozen importlib._bootstrap>", line 488, in _call_with_frames_removed
  File "/home/ec2-user/flask_miniproject1/wsgi.py", line 3, in <module>
    app = create_app()
          ^^^^^^^^^^^^
  File "/home/ec2-user/flask_miniproject1/app/__init__.py", line 34, in create_app
    from .routes.answers import answer_blp
  File "/home/ec2-user/flask_miniproject1/app/routes/answers.py", line 6, in <module>
    answer_blp = Blueprint('Answer', 'answer', url_prefix='/submit',strict_slashes=False)
                 ^^^^^^^^^^^^^^^^^^^^^^^^^^^^^^^^^^^^^^^^^^^^^^^^^^^^^^^^^^^^^^^^^^^^^^^^
  File "/home/ec2-user/flask_miniproject1/.venv/lib64/python3.12/site-packages/flask_smorest/blueprint.py", line 74, in __init__
    super().__init__(*args, **kwargs)
TypeError: Blueprint.__init__() got an unexpected keyword argument 'strict_slashes'
[2025-01-15 06:01:14 +0000] [5858] [INFO] Worker exiting (pid: 5858)
[2025-01-15 06:01:14 +0000] [5859] [ERROR] Exception in worker process
Traceback (most recent call last):
  File "/home/ec2-user/flask_miniproject1/.venv/lib64/python3.12/site-packages/gunicorn/arbiter.py", line 608, in spawn_worker
    worker.init_process()
  File "/home/ec2-user/flask_miniproject1/.venv/lib64/python3.12/site-packages/gunicorn/workers/base.py", line 135, in init_process
    self.load_wsgi()
  File "/home/ec2-user/flask_miniproject1/.venv/lib64/python3.12/site-packages/gunicorn/workers/base.py", line 147, in load_wsgi
    self.wsgi = self.app.wsgi()
                ^^^^^^^^^^^^^^^
  File "/home/ec2-user/flask_miniproject1/.venv/lib64/python3.12/site-packages/gunicorn/app/base.py", line 66, in wsgi
    self.callable = self.load()
                    ^^^^^^^^^^^
  File "/home/ec2-user/flask_miniproject1/.venv/lib64/python3.12/site-packages/gunicorn/app/wsgiapp.py", line 57, in load
    return self.load_wsgiapp()
           ^^^^^^^^^^^^^^^^^^^
  File "/home/ec2-user/flask_miniproject1/.venv/lib64/python3.12/site-packages/gunicorn/app/wsgiapp.py", line 47, in load_wsgiapp
    return util.import_app(self.app_uri)
           ^^^^^^^^^^^^^^^^^^^^^^^^^^^^^
  File "/home/ec2-user/flask_miniproject1/.venv/lib64/python3.12/site-packages/gunicorn/util.py", line 370, in import_app
    mod = importlib.import_module(module)
          ^^^^^^^^^^^^^^^^^^^^^^^^^^^^^^^
  File "/usr/lib64/python3.12/importlib/__init__.py", line 90, in import_module
    return _bootstrap._gcd_import(name[level:], package, level)
           ^^^^^^^^^^^^^^^^^^^^^^^^^^^^^^^^^^^^^^^^^^^^^^^^^^^^
  File "<frozen importlib._bootstrap>", line 1387, in _gcd_import
  File "<frozen importlib._bootstrap>", line 1360, in _find_and_load
  File "<frozen importlib._bootstrap>", line 1331, in _find_and_load_unlocked
  File "<frozen importlib._bootstrap>", line 935, in _load_unlocked
  File "<frozen importlib._bootstrap_external>", line 995, in exec_module
  File "<frozen importlib._bootstrap>", line 488, in _call_with_frames_removed
  File "/home/ec2-user/flask_miniproject1/wsgi.py", line 3, in <module>
    app = create_app()
          ^^^^^^^^^^^^
  File "/home/ec2-user/flask_miniproject1/app/__init__.py", line 34, in create_app
    from .routes.answers import answer_blp
  File "/home/ec2-user/flask_miniproject1/app/routes/answers.py", line 6, in <module>
    answer_blp = Blueprint('Answer', 'answer', url_prefix='/submit',strict_slashes=False)
                 ^^^^^^^^^^^^^^^^^^^^^^^^^^^^^^^^^^^^^^^^^^^^^^^^^^^^^^^^^^^^^^^^^^^^^^^^
  File "/home/ec2-user/flask_miniproject1/.venv/lib64/python3.12/site-packages/flask_smorest/blueprint.py", line 74, in __init__
    super().__init__(*args, **kwargs)
TypeError: Blueprint.__init__() got an unexpected keyword argument 'strict_slashes'
[2025-01-15 06:01:14 +0000] [5859] [INFO] Worker exiting (pid: 5859)
[2025-01-15 06:01:14 +0000] [5861] [ERROR] Exception in worker process
Traceback (most recent call last):
  File "/home/ec2-user/flask_miniproject1/.venv/lib64/python3.12/site-packages/gunicorn/arbiter.py", line 608, in spawn_worker
    worker.init_process()
  File "/home/ec2-user/flask_miniproject1/.venv/lib64/python3.12/site-packages/gunicorn/workers/base.py", line 135, in init_process
    self.load_wsgi()
  File "/home/ec2-user/flask_miniproject1/.venv/lib64/python3.12/site-packages/gunicorn/workers/base.py", line 147, in load_wsgi
    self.wsgi = self.app.wsgi()
                ^^^^^^^^^^^^^^^
  File "/home/ec2-user/flask_miniproject1/.venv/lib64/python3.12/site-packages/gunicorn/app/base.py", line 66, in wsgi
    self.callable = self.load()
                    ^^^^^^^^^^^
  File "/home/ec2-user/flask_miniproject1/.venv/lib64/python3.12/site-packages/gunicorn/app/wsgiapp.py", line 57, in load
    return self.load_wsgiapp()
           ^^^^^^^^^^^^^^^^^^^
  File "/home/ec2-user/flask_miniproject1/.venv/lib64/python3.12/site-packages/gunicorn/app/wsgiapp.py", line 47, in load_wsgiapp
    return util.import_app(self.app_uri)
           ^^^^^^^^^^^^^^^^^^^^^^^^^^^^^
  File "/home/ec2-user/flask_miniproject1/.venv/lib64/python3.12/site-packages/gunicorn/util.py", line 370, in import_app
    mod = importlib.import_module(module)
          ^^^^^^^^^^^^^^^^^^^^^^^^^^^^^^^
  File "/usr/lib64/python3.12/importlib/__init__.py", line 90, in import_module
    return _bootstrap._gcd_import(name[level:], package, level)
           ^^^^^^^^^^^^^^^^^^^^^^^^^^^^^^^^^^^^^^^^^^^^^^^^^^^^
  File "<frozen importlib._bootstrap>", line 1387, in _gcd_import
  File "<frozen importlib._bootstrap>", line 1360, in _find_and_load
  File "<frozen importlib._bootstrap>", line 1331, in _find_and_load_unlocked
  File "<frozen importlib._bootstrap>", line 935, in _load_unlocked
  File "<frozen importlib._bootstrap_external>", line 995, in exec_module
  File "<frozen importlib._bootstrap>", line 488, in _call_with_frames_removed
  File "/home/ec2-user/flask_miniproject1/wsgi.py", line 3, in <module>
    app = create_app()
          ^^^^^^^^^^^^
  File "/home/ec2-user/flask_miniproject1/app/__init__.py", line 34, in create_app
    from .routes.answers import answer_blp
  File "/home/ec2-user/flask_miniproject1/app/routes/answers.py", line 6, in <module>
    answer_blp = Blueprint('Answer', 'answer', url_prefix='/submit',strict_slashes=False)
                 ^^^^^^^^^^^^^^^^^^^^^^^^^^^^^^^^^^^^^^^^^^^^^^^^^^^^^^^^^^^^^^^^^^^^^^^^
  File "/home/ec2-user/flask_miniproject1/.venv/lib64/python3.12/site-packages/flask_smorest/blueprint.py", line 74, in __init__
    super().__init__(*args, **kwargs)
TypeError: Blueprint.__init__() got an unexpected keyword argument 'strict_slashes'
[2025-01-15 06:01:14 +0000] [5861] [INFO] Worker exiting (pid: 5861)
[2025-01-15 06:01:14 +0000] [5863] [ERROR] Exception in worker process
Traceback (most recent call last):
  File "/home/ec2-user/flask_miniproject1/.venv/lib64/python3.12/site-packages/gunicorn/arbiter.py", line 608, in spawn_worker
    worker.init_process()
  File "/home/ec2-user/flask_miniproject1/.venv/lib64/python3.12/site-packages/gunicorn/workers/base.py", line 135, in init_process
    self.load_wsgi()
  File "/home/ec2-user/flask_miniproject1/.venv/lib64/python3.12/site-packages/gunicorn/workers/base.py", line 147, in load_wsgi
    self.wsgi = self.app.wsgi()
                ^^^^^^^^^^^^^^^
  File "/home/ec2-user/flask_miniproject1/.venv/lib64/python3.12/site-packages/gunicorn/app/base.py", line 66, in wsgi
    self.callable = self.load()
                    ^^^^^^^^^^^
  File "/home/ec2-user/flask_miniproject1/.venv/lib64/python3.12/site-packages/gunicorn/app/wsgiapp.py", line 57, in load
    return self.load_wsgiapp()
           ^^^^^^^^^^^^^^^^^^^
  File "/home/ec2-user/flask_miniproject1/.venv/lib64/python3.12/site-packages/gunicorn/app/wsgiapp.py", line 47, in load_wsgiapp
    return util.import_app(self.app_uri)
           ^^^^^^^^^^^^^^^^^^^^^^^^^^^^^
  File "/home/ec2-user/flask_miniproject1/.venv/lib64/python3.12/site-packages/gunicorn/util.py", line 370, in import_app
    mod = importlib.import_module(module)
          ^^^^^^^^^^^^^^^^^^^^^^^^^^^^^^^
  File "/usr/lib64/python3.12/importlib/__init__.py", line 90, in import_module
    return _bootstrap._gcd_import(name[level:], package, level)
           ^^^^^^^^^^^^^^^^^^^^^^^^^^^^^^^^^^^^^^^^^^^^^^^^^^^^
  File "<frozen importlib._bootstrap>", line 1387, in _gcd_import
  File "<frozen importlib._bootstrap>", line 1360, in _find_and_load
  File "<frozen importlib._bootstrap>", line 1331, in _find_and_load_unlocked
  File "<frozen importlib._bootstrap>", line 935, in _load_unlocked
  File "<frozen importlib._bootstrap_external>", line 995, in exec_module
  File "<frozen importlib._bootstrap>", line 488, in _call_with_frames_removed
  File "/home/ec2-user/flask_miniproject1/wsgi.py", line 3, in <module>
    app = create_app()
          ^^^^^^^^^^^^
  File "/home/ec2-user/flask_miniproject1/app/__init__.py", line 34, in create_app
    from .routes.answers import answer_blp
  File "/home/ec2-user/flask_miniproject1/app/routes/answers.py", line 6, in <module>
    answer_blp = Blueprint('Answer', 'answer', url_prefix='/submit',strict_slashes=False)
                 ^^^^^^^^^^^^^^^^^^^^^^^^^^^^^^^^^^^^^^^^^^^^^^^^^^^^^^^^^^^^^^^^^^^^^^^^
  File "/home/ec2-user/flask_miniproject1/.venv/lib64/python3.12/site-packages/flask_smorest/blueprint.py", line 74, in __init__
    super().__init__(*args, **kwargs)
TypeError: Blueprint.__init__() got an unexpected keyword argument 'strict_slashes'
[2025-01-15 06:01:14 +0000] [5863] [INFO] Worker exiting (pid: 5863)
[2025-01-15 06:01:15 +0000] [5857] [ERROR] Worker (pid:5858) exited with code 3
[2025-01-15 06:01:15 +0000] [5857] [ERROR] Worker (pid:5863) was sent SIGTERM!
[2025-01-15 06:01:15 +0000] [5857] [ERROR] Worker (pid:5861) was sent SIGTERM!
[2025-01-15 06:01:15 +0000] [5857] [ERROR] Worker (pid:5859) was sent SIGTERM!
[2025-01-15 06:01:15 +0000] [5857] [ERROR] Shutting down: Master
[2025-01-15 06:01:15 +0000] [5857] [ERROR] Reason: Worker failed to boot.
[2025-01-15 06:02:40 +0000] [5973] [INFO] Starting gunicorn 23.0.0
[2025-01-15 06:02:40 +0000] [5973] [INFO] Listening at: http://127.0.0.1:8000 (5973)
[2025-01-15 06:02:40 +0000] [5973] [INFO] Using worker: sync
[2025-01-15 06:02:40 +0000] [5975] [INFO] Booting worker with pid: 5975
[2025-01-15 06:02:40 +0000] [5976] [INFO] Booting worker with pid: 5976
[2025-01-15 06:02:40 +0000] [5979] [INFO] Booting worker with pid: 5979
[2025-01-15 06:02:40 +0000] [5980] [INFO] Booting worker with pid: 5980
[2025-01-15 06:05:03,335] ERROR in app: Exception on /submit/ [POST]
Traceback (most recent call last):
  File "/home/ec2-user/flask_miniproject1/.venv/lib64/python3.12/site-packages/flask/app.py", line 1511, in wsgi_app
    response = self.full_dispatch_request()
               ^^^^^^^^^^^^^^^^^^^^^^^^^^^^
  File "/home/ec2-user/flask_miniproject1/.venv/lib64/python3.12/site-packages/flask/app.py", line 919, in full_dispatch_request
    rv = self.handle_user_exception(e)
         ^^^^^^^^^^^^^^^^^^^^^^^^^^^^^
  File "/home/ec2-user/flask_miniproject1/.venv/lib64/python3.12/site-packages/flask/app.py", line 917, in full_dispatch_request
    rv = self.dispatch_request()
         ^^^^^^^^^^^^^^^^^^^^^^^
  File "/home/ec2-user/flask_miniproject1/.venv/lib64/python3.12/site-packages/flask/app.py", line 902, in dispatch_request
    return self.ensure_sync(self.view_functions[rule.endpoint])(**view_args)  # type: ignore[no-any-return]
           ^^^^^^^^^^^^^^^^^^^^^^^^^^^^^^^^^^^^^^^^^^^^^^^^^^^^^^^^^^^^^^^^^
  File "/home/ec2-user/flask_miniproject1/.venv/lib64/python3.12/site-packages/flask/views.py", line 110, in view
    return current_app.ensure_sync(self.dispatch_request)(**kwargs)  # type: ignore[no-any-return]
           ^^^^^^^^^^^^^^^^^^^^^^^^^^^^^^^^^^^^^^^^^^^^^^^^^^^^^^^^
  File "/home/ec2-user/flask_miniproject1/.venv/lib64/python3.12/site-packages/flask/views.py", line 191, in dispatch_request
    return current_app.ensure_sync(meth)(**kwargs)  # type: ignore[no-any-return]
           ^^^^^^^^^^^^^^^^^^^^^^^^^^^^^^^^^^^^^^^
  File "/home/ec2-user/flask_miniproject1/app/routes/answers.py", line 15, in post
    user_id = data.get("userId")
              ^^^^^^^^
AttributeError: 'list' object has no attribute 'get'
[2025-01-15 06:06:52,140] ERROR in app: Exception on /submit/ [POST]
Traceback (most recent call last):
  File "/home/ec2-user/flask_miniproject1/.venv/lib64/python3.12/site-packages/flask/app.py", line 1511, in wsgi_app
    response = self.full_dispatch_request()
               ^^^^^^^^^^^^^^^^^^^^^^^^^^^^
  File "/home/ec2-user/flask_miniproject1/.venv/lib64/python3.12/site-packages/flask/app.py", line 919, in full_dispatch_request
    rv = self.handle_user_exception(e)
         ^^^^^^^^^^^^^^^^^^^^^^^^^^^^^
  File "/home/ec2-user/flask_miniproject1/.venv/lib64/python3.12/site-packages/flask/app.py", line 917, in full_dispatch_request
    rv = self.dispatch_request()
         ^^^^^^^^^^^^^^^^^^^^^^^
  File "/home/ec2-user/flask_miniproject1/.venv/lib64/python3.12/site-packages/flask/app.py", line 902, in dispatch_request
    return self.ensure_sync(self.view_functions[rule.endpoint])(**view_args)  # type: ignore[no-any-return]
           ^^^^^^^^^^^^^^^^^^^^^^^^^^^^^^^^^^^^^^^^^^^^^^^^^^^^^^^^^^^^^^^^^
  File "/home/ec2-user/flask_miniproject1/.venv/lib64/python3.12/site-packages/flask/views.py", line 110, in view
    return current_app.ensure_sync(self.dispatch_request)(**kwargs)  # type: ignore[no-any-return]
           ^^^^^^^^^^^^^^^^^^^^^^^^^^^^^^^^^^^^^^^^^^^^^^^^^^^^^^^^
  File "/home/ec2-user/flask_miniproject1/.venv/lib64/python3.12/site-packages/flask/views.py", line 191, in dispatch_request
    return current_app.ensure_sync(meth)(**kwargs)  # type: ignore[no-any-return]
           ^^^^^^^^^^^^^^^^^^^^^^^^^^^^^^^^^^^^^^^
  File "/home/ec2-user/flask_miniproject1/app/routes/answers.py", line 15, in post
    user_id = data.get("userId")
              ^^^^^^^^
AttributeError: 'list' object has no attribute 'get'
[2025-01-15 06:07:01 +0000] [5973] [INFO] Handling signal: term
[2025-01-15 06:07:01 +0000] [5975] [INFO] Worker exiting (pid: 5975)
[2025-01-15 06:07:01 +0000] [5976] [INFO] Worker exiting (pid: 5976)
[2025-01-15 06:07:01 +0000] [5979] [INFO] Worker exiting (pid: 5979)
[2025-01-15 06:07:01 +0000] [5980] [INFO] Worker exiting (pid: 5980)
[2025-01-15 06:07:01 +0000] [5973] [ERROR] Worker (pid:5975) was sent SIGTERM!
[2025-01-15 06:07:01 +0000] [5973] [ERROR] Worker (pid:5976) was sent SIGTERM!
[2025-01-15 06:07:01 +0000] [5973] [ERROR] Worker (pid:5979) was sent SIGTERM!
[2025-01-15 06:07:01 +0000] [5973] [INFO] Shutting down: Master
[2025-01-15 06:07:03 +0000] [6160] [INFO] Starting gunicorn 23.0.0
[2025-01-15 06:07:03 +0000] [6160] [INFO] Listening at: http://127.0.0.1:8000 (6160)
[2025-01-15 06:07:03 +0000] [6160] [INFO] Using worker: sync
[2025-01-15 06:07:03 +0000] [6162] [INFO] Booting worker with pid: 6162
[2025-01-15 06:07:03 +0000] [6163] [INFO] Booting worker with pid: 6163
[2025-01-15 06:07:03 +0000] [6166] [INFO] Booting worker with pid: 6166
[2025-01-15 06:07:03 +0000] [6167] [INFO] Booting worker with pid: 6167
[2025-01-15 06:07:06,081] ERROR in app: Exception on /submit/ [POST]
Traceback (most recent call last):
  File "/home/ec2-user/flask_miniproject1/.venv/lib64/python3.12/site-packages/flask/app.py", line 1511, in wsgi_app
    response = self.full_dispatch_request()
               ^^^^^^^^^^^^^^^^^^^^^^^^^^^^
  File "/home/ec2-user/flask_miniproject1/.venv/lib64/python3.12/site-packages/flask/app.py", line 919, in full_dispatch_request
    rv = self.handle_user_exception(e)
         ^^^^^^^^^^^^^^^^^^^^^^^^^^^^^
  File "/home/ec2-user/flask_miniproject1/.venv/lib64/python3.12/site-packages/flask/app.py", line 917, in full_dispatch_request
    rv = self.dispatch_request()
         ^^^^^^^^^^^^^^^^^^^^^^^
  File "/home/ec2-user/flask_miniproject1/.venv/lib64/python3.12/site-packages/flask/app.py", line 902, in dispatch_request
    return self.ensure_sync(self.view_functions[rule.endpoint])(**view_args)  # type: ignore[no-any-return]
           ^^^^^^^^^^^^^^^^^^^^^^^^^^^^^^^^^^^^^^^^^^^^^^^^^^^^^^^^^^^^^^^^^
  File "/home/ec2-user/flask_miniproject1/.venv/lib64/python3.12/site-packages/flask/views.py", line 110, in view
    return current_app.ensure_sync(self.dispatch_request)(**kwargs)  # type: ignore[no-any-return]
           ^^^^^^^^^^^^^^^^^^^^^^^^^^^^^^^^^^^^^^^^^^^^^^^^^^^^^^^^
  File "/home/ec2-user/flask_miniproject1/.venv/lib64/python3.12/site-packages/flask/views.py", line 191, in dispatch_request
    return current_app.ensure_sync(meth)(**kwargs)  # type: ignore[no-any-return]
           ^^^^^^^^^^^^^^^^^^^^^^^^^^^^^^^^^^^^^^^
  File "/home/ec2-user/flask_miniproject1/app/routes/answers.py", line 15, in post
    user_id = data.get("userId")
              ^^^^^^^^
AttributeError: 'list' object has no attribute 'get'
[2025-01-15 06:09:17 +0000] [6160] [INFO] Handling signal: term
[2025-01-15 06:09:17 +0000] [6162] [INFO] Worker exiting (pid: 6162)
[2025-01-15 06:09:17 +0000] [6163] [INFO] Worker exiting (pid: 6163)
[2025-01-15 06:09:17 +0000] [6166] [INFO] Worker exiting (pid: 6166)
[2025-01-15 06:09:17 +0000] [6167] [INFO] Worker exiting (pid: 6167)
[2025-01-15 06:09:17 +0000] [6160] [ERROR] Worker (pid:6162) was sent SIGTERM!
[2025-01-15 06:09:17 +0000] [6160] [ERROR] Worker (pid:6163) was sent SIGTERM!
[2025-01-15 06:09:17 +0000] [6160] [ERROR] Worker (pid:6166) was sent SIGTERM!
[2025-01-15 06:09:18 +0000] [6160] [INFO] Shutting down: Master
[2025-01-15 06:09:20 +0000] [6345] [INFO] Starting gunicorn 23.0.0
[2025-01-15 06:09:20 +0000] [6345] [INFO] Listening at: http://127.0.0.1:8000 (6345)
[2025-01-15 06:09:20 +0000] [6345] [INFO] Using worker: sync
[2025-01-15 06:09:20 +0000] [6347] [INFO] Booting worker with pid: 6347
[2025-01-15 06:09:20 +0000] [6349] [INFO] Booting worker with pid: 6349
[2025-01-15 06:09:20 +0000] [6348] [INFO] Booting worker with pid: 6348
[2025-01-15 06:09:20 +0000] [6352] [INFO] Booting worker with pid: 6352
